Workbook

Sheet README
A1: Minzhong land deeds: OCR tables
A3: Source
A4: OCR_results/ (407 pages, 234 items) in eastd143a-team-Youxiao, joined to the catalogue chinese_land_records_235.csv (jackieldyh branch) by Pitt ID.
A6: Sheets
A7: Documents: one row per OCR page. Catalogue fields (reliable), auto-extracted OCR fields (need checking), 0/1 formula flags, OCR quality counts, cleaned text.
A8: Narrative_moves: the 12-move structure of a private deed, with counts.
A9: Formulae_by_period: private-deed formulae by period.
A10: Official_formulae: bureaucratic formulae by regime (Qing / Republic / PRC).
A11: Deed_types: every 立…契 title found, grouped into stages.
A12: Land_and_money: land-layer and currency vocabulary.
A13: Deed_chains: documents that cite one another.
A14: OCR_issues: known recognition errors and their effect.
... A23: Companion analysis page: https://claude.ai/artifact/XqAXHuUGLNm4J5q7sqxaro

Sheet Documents
A1: Page ID | B1: Item ID | C1: Page | D1: Year (start) | E1: Year (end) | F1: Period | G1: Regime | H1: Catalogue date | I1: County (normalised) | J1: Place (catalogue) | K1: Catalogue nature | L1: Owner (catalogue) | M1: Seller (catalogue) | N1: Buyer (catalogue) | O1: Box / folder | P1: Page type | Q1: Deed title 立…契 | R1: Dates in text | S1: Seller / author (OCR) | T1: Buyer X處 (OCR) | U1: Price phrase (OCR) | V1: Currency | W1: Location 坐落 | X1: Place-name 土名 | Y1: Land terms | Z1: Middleman 中人 | AA1: Scribe 代筆 | AB1: Witnesses 在見 | AC1: Female consent 知契…氏 | AD1: Redemption term (yrs) | AE1: Form headings | AF1: Issuing office | AG1: Holder 業戶/右給 | AH1: Serial 字第…號 | AI1: 今因 motive | AJ1: 自願 voluntary | AK1: 託中 mediated | AL1: 三面言議 | AM1: 即日交足 paid | AN1: 無重典/來歷 warranty | AO1: 出頭承當 seller answers | AP1: 取贖 redemption | AQ1: 永遠 perpetual | AR1: 無反悔/異言 | AS1: 今欲有憑 closing | AT1: 併繳 prior deeds | AU1: 內改 correction | AV1: 吉日 | AW1: 為…事 | AX1: 案奉/等因奉此 | AY1: 須至…者 | AZ1: 右給… | BA1: 罰/逾限 | BB1: 訴訟/憑證 | BC1: Characters | BD1: Seal/image blocks | BE1: Truncated blocks | BF1: English mixed in | BG1: Pitt URL | BH1: OCR text (cleaned, ≤3000 chars)
A2: 31735064607413_001 | B2: 31735064607413 | C2: 1 | D2: 1886 | E2: 1886 | F2: =IF(D2="","?",IF(D2<1796,"pre-1796",IF(D2<1912,"1796-1911",IF(D2<1949,"1912-1948","1949+")))) -> 1796-1911 | G2: =IF(D2="","?",IF(D2<1912,"Qing",IF(D2<1949,"Republic","PRC"))) -> Qing | H2: 1886 | I2: 福清 | J2: 福建省福清縣 | K2: Government | L2: 高恭地 | O2: Box 2, Folder 60 | P2: Other / fragment | AE2: 契 | 尾 | AI2: 0 | AJ2: 0 | AK2: 0 | AL2: 0 | AM2: 0 | AN2: 0 | AO2: 0 | AP2: 0 | AQ2: 0 | AR2: 0 | AS2: 0 | AT2: 0 | AU2: 0 | AV2: 0 | AW2: 0 | AX2: 1 | AY2: 0 | AZ2: 0 | BA2: 0 | BB2: 0 | BC2: 131 | BD2: 1 | BE2: 2 | BF2: 0 | BG2: https://digital.library.pitt.edu/islandora/object/pitt:31735064607413 | BH2: 契尾布九三三雷查該縣於十五年正月二十日奉准部咨開司案所有本縣舊有印信等項應行更換...查該縣於十五年正月二十日奉准部咨開司案所有本縣舊有印信等項應行更換...高恭地聖蓮店一間高山市街致千卷百肆拾肆福清高恭地准此拾捌年捌月三...拾...日陸拾叁捌拾分陸拾叁捌拾分
A3: 31735064607421_001 | B3: 31735064607421 | C3: 1 | D3: 1946 | E3: 1951 | F3: =IF(D3="","?",IF(D3<1796,"pre-1796",IF(D3<1912,"1796-1911",IF(D3<1949,"1912-1948","1949+")))) -> 1912-1948 | G3: =IF(D3="","?",IF(D3<1912,"Qing",IF(D3<1949,"Republic","PRC"))) -> Republic | H3: 1946/1951 | I3: 福清 | J3: 福建省福清縣 | K3: Government | M3: 張學車 | N3: 陳書寶 | 張學車 | O3: Box 4, Folder 173 | P3: Private deed + state certificate | Q3: 立契 | R3: 公元一九四六年; 中華民國三十五年; 民國35年; 民國三十五年 | S3: 日期上手 | U3: 幣壹佰捌拾萬元; 幣壹萬元正 | V3: 人民幣; 國幣 | W3: 福州市五甲街 | Y3: 店屋; 地基; 基地 | AI3: 1 | AJ3: 0 | AK3: 1 | AL3: 0 | AM3: 1 | AN3: 1 | AO3: 1 | AP3: 0 | AQ3: 0 | AR3: 1 | AS3: 0 | AT3: 1 | AU3: 0 | AV3: 0 | AW3: 0 | AX3: 0 | AY3: 0 | AZ3: 0 | BA3: 0 | BB3: 0 | BC3: 571 | BD3: 5 | BE3: 0 | BF3: 0 | BG3: https://digital.library.pitt.edu/islandora/object/pitt:31735064607421 | BH3: 元九月市長日發給收執繳納稅額屋價屋式四至面積坐落不動產種類姓名承受人人民幣壹拾萬捌仟九人民幣壹佰捌拾萬元坐西向東五柱二棚樓屋直進壹欄南至隣屋九九九地號西至隣屋九九九地號北至隣屋九九九地號零畝零分伍厘肆毫五甲街門牌二七號宅陳寶學車附註監證人簽名蓋章立契日期上手原契區段別姓名原所有姓名公元一九四六年六月三區二二段九九八地號(此契人受未權有原請中交聯此)中華民國三十五年六月日賣斷契張學車民國35年9月28日21998219981401立賣斷契張學車民國三十五年五月間買斷王依增店屋(座坐落福州市五甲街地方門牌19號屬3區11段1401地號面積14毫定着物坐西向東五柱直進單欄排上下堵木尺橫澗前後均壹丈長深寸零直深三丈四尺零東至五甲街西至隣屋九九九號南至隣屋九九九號北至隣屋九九七號上至椽瓦天下至礫石地基地六至叙明屋內所有附屬物品一切俱全今因別置托中將上列店屋連同基地賣斷與陳書寶處為業議定斷國幣壹萬元正其款即日收足其屋即聽陳家移轉登記享受所有權收益使用自由處分串自賣斷之後價定終休永不敢別生枝節有言借湊畫牘之理但此店屋係車自置與房族上下人等無干亦無重疊典押來歷各等情如有發生意外轉輾均由車得欺人處理負責不涉買主之事彼此兩願各無反悔恐口易翻特立賣斷契壹紙並繳王依增斷契壹紙樊汝濟斷契壹紙楊生春斷契稅証各壹紙鄔細細佛斷契壹紙稅証式紙共成捌紙付執為据
A4: 31735064607439_001 | B4: 31735064607439 | C4: 1 | D4: 1929 | E4: 1929 | F4: =IF(D4="","?",IF(D4<1796,"pre-1796",IF(D4<1912,"1796-1911",IF(D4<1949,"1912-1948","1949+")))) -> 1912-1948 | G4: =IF(D4="","?",IF(D4<1912,"Qing",IF(D4<1949,"Republic","PRC"))) -> Republic | H4: 1929 | I4: 古田 | J4: 福建省古田縣 | K4: Government | L4: 林枝貴 | O4: Box 3, Folder 139 | P4: Official form | Q4: 立之不動產舊契 | R4: 中華民國十年 | U4: 價壹萬零九百零四元 | W4: 四至原契已載明白遵章呈驗應納紙價 | AE4: 驗 稅 契 證 | 福建財政廳 | AF4: 福建財政廳 | AG4: 林枝秀 | AH4: 契證新字第 306 號 | AI4: 0 | AJ4: 0 | AK4: 0 | AL4: 0 | AM4: 0 | AN4: 0 | AO4: 0 | AP4: 0 | AQ4: 0 | AR4: 0 | AS4: 1 | AT4: 1 | AU4: 0 | AV4: 0 | AW4: 1 | AX4: 1 | AY4: 1 | AZ4: 1 | BA4: 1 | BB4: 1 | BC4: 318 | BD4: 2 | BE4: 2 | BF4: 0 | BG4: https://digital.library.pitt.edu/islandora/object/pitt:31735064607439 | BH4: 驗稅契證福建財政廳為給發驗稅契證事案奉國民政府財政部訓令頒發驗契暫行條例及各省驗契章程凡在此次開辦驗契以前成立之不動產舊契無已稅未稅均應一律限期呈驗換發新契紙倘逾限不呈驗遇有訴訟不能作為憑證如經人告發或官廳查出者並加以處罰業由財政部咨行司法部通飭遵辦以為匿驗者等因奉此當經擬具徵收方法電奉財政部核准照辦並已訂定本堂驗契補充辦法分別通令布告遵照在案茲據業戶林枝秀呈繳已稅田契壹張產價壹萬零九百零四元坐落四至原契已載明白遵章呈驗應納紙價壹元八角分註冊費五角附加教育費貳角業已如數收訖除註冊外合填驗稅契證粘連原契給收執管業須至契證者奉財政廳令定逾限按屆遞加紙價十分之二右給業戶林枝秀准此中華民國十年八月日給小契證新字第306號系所......
A5: 31735064607447_001 | B5: 31735064607447 | C5: 1 | D5: 1866 | E5: 1866 | F5: =IF(D5="","?",IF(D5<1796,"pre-1796",IF(D5<1912,"1796-1911",IF(D5<1949,"1912-1948","1949+")))) -> 1796-1911 | G5: =IF(D5="","?",IF(D5<1912,"Qing",IF(D5<1949,"Republic","PRC"))) -> Qing | H5: 1866 | I5: 閩侯（閩縣・侯官・林森） | J5: 福建省閩邑 | K5: Personal | M5: 林春源 | O5: Box 1, Folder 41 | P5: Private deed | Q5: 立賣斷契 | R5: 同治伍年 | S5: 林春源 | U5: 銀庫砵壹拾貳兩正 | W5: 閩邑嘉崇里秋龍巷 | Z5: 將此地屋賣斷; 陳友梅 | AA5: 張秉中 | AB5: 堂弟 | AI5: 1 | AJ5: 1 | AK5: 1 | AL5: 0 | AM5: 1 | AN5: 1 | AO5: 1 | AP5: 1 | AQ5: 1 | AR5: 0 | AS5: 1 | AT5: 0 | AU5: 1 | AV5: 1 | AW5: 0 | AX5: 0 | AY5: 0 | AZ5: 0 | BA5: 0 | BB5: 0 | BC5: 339 | BD5: 0 | BE5: 0 | BF5: 0 | BG5: https://digital.library.pitt.edu/islandora/object/pitt:31735064607447 | BH5: 立賣斷契林春源承父遺下有式柱破屋壹直參堵右邊更有殘地壹塊在王家店後坐落閩邑嘉崇里秋龍巷地方其屋前至王家店後至王家屋左至李家屋右至翰家屋其地前至翰家屋後至王家屋肆至載明今因乏用托中友將此地屋賣斷王處為業參面言議本日賣斷得地屋價足色鏡銀庫砵壹拾貳兩正其銀即日隨券收清其地屋俱聽王家掌管永遠為世業價足心愿永斷葛藤不敢別生枝節異說翻言以至後日亦不敢言取贖湊盡之事但此地屋係源遺父遺已業歷掌無異與親疏房份伯叔兄弟侄等無干並未曾重張曲當他人財物如有來歷不明承葛各等情弊源自愿出頭承當與王家毫無干涉其原契夾連別業不得繳賣今欲有憑立賣斷契壹紙付執永遠為照內塗遺壹字標照陸王姓在店後居住者出入皆由王家店內而行標照壹同治伍年參月吉日立賣斷契林春源謹堂叔長發在見堂弟春榮樓中友陳友梅樓地保代筆張秉中謹
A6: 31735064607454_001 | B6: 31735064607454 | C6: 1 | D6: 1862 | E6: 1862 | F6: =IF(D6="","?",IF(D6<1796,"pre-1796",IF(D6<1912,"1796-1911",IF(D6<1949,"1912-1948","1949+")))) -> 1796-1911 | G6: =IF(D6="","?",IF(D6<1912,"Qing",IF(D6<1949,"Republic","PRC"))) -> Qing | H6: 1862 | K6: Personal | M6: 张华富 | O6: Box 1, Folder 36 | P6: Private deed + state certificate | Q6: 立賣斷山契 | S6: 張華富 | U6: 價銅錢捌仟五百文正; 價銅錢捌仟伍百文正 | W6: 田里南坑上名鳳坑仔即目上至崗頂下 | Y6: 皮骨; 茶山; 山場 | Z6: 張華春 | AA6: 詹王佐鑾 | AI6: 0 | AJ6: 1 | AK6: 1 | AL6: 1 | AM6: 1 | AN6: 1 | AO6: 0 | AP6: 0 | AQ6: 1 | AR6: 0 | AS6: 1 | AT6: 0 | AU6: 0 | AV6: 0 | AW6: 0 | AX6: 0 | AY6: 0 | AZ6: 0 | BA6: 0 | BB6: 0 | BC6: 308 | BD6: 0 | BE6: 0 | BF6: 0 | BG6: https://digital.library.pitt.edu/islandora/object/pitt:31735064607454 | BH6: 立賣斷山契人張華富承祖遺下置有皮骨茶山壹片坐落田里南坑上名鳳坑仔即目上至崗頂下至日榜左至本張宅分水為界右至亦本張分水為界今來俱出四至明白茲因缺錢應用情愿託中說諭甘將榕桐竹茶雜木皮骨山場盡立契出賣斷與程金寶名下邊為業當日三面言議時值價銅錢捌仟五百文正成契之日一頓交足不少分文並無債化員準折之類亦無重典復賣之理所賣斷其山的係自己股內物業與親房伯叔兄弟侄人等各不相干自賣斷之後任從買者永遠管業收租不敢阻執此係兩家甘允各無異說今欲有憑故立賣斷契為照當日實交得賣斷價銅錢捌仟伍百文正足訖所有上手契卷一時不及尋出日後尋出不堪行用執照同治壬戌元年柒月日立賣斷契人張華富張說諭人張喜孫張為中人張華春在見人張華應張代筆人詹王佐鑾張華富
A7: 31735064607462_001 | B7: 31735064607462 | C7: 1 | D7: 1931 | E7: 1931 | F7: =IF(D7="","?",IF(D7<1796,"pre-1796",IF(D7<1912,"1796-1911",IF(D7<1949,"1912-1948","1949+")))) -> 1912-1948 | G7: =IF(D7="","?",IF(D7<1912,"Qing",IF(D7<1949,"Republic","PRC"))) -> Republic | H7: 1931 | K7: Personal | M7: 高天钏 | N7: 郑祚龙 | O7: Box 3, Folder 142 | P7: Private deed | Q7: 立送字 | R7: 民國貳拾年 | S7: 高天釗 | X7: 過洋 | Y7: 墳 | AA7: 經手人族 | AB7: 兄居碑誌 | AI7: 1 | AJ7: 0 | AK7: 0 | AL7: 0 | AM7: 0 | AN7: 1 | AO7: 1 | AP7: 0 | AQ7: 1 | AR7: 1 | AS7: 1 | AT7: 0 | AU7: 0 | AV7: 0 | AW7: 0 | AX7: 0 | AY7: 0 | AZ7: 0 | BA7: 0 | BB7: 0 | BC7: 255 | BD7: 0 | BE7: 0 | BF7: 0 | BG7: https://digital.library.pitt.edu/islandora/object/pitt:31735064607462 | BH7: 立送字永遠山地契高天釗承祖純剛公派下有壙穴坐產土名過洋山北山墓埕下大坪園下有吉穴上至大坪園下至山坡左至居耐墓右至居炉墓親歷四至明白今因要用將此山地送友鄭祚龍處造墳葬親即听鄭家破土興工造墳葬親面約前無遮蔽後無開鑿金至於鄭家高者鋪平低者補滿堆疊圓山嶺仍憑順處一派路徑通行通用開門放水听從其便係天釗但此山地承祖物業前別房伯叔兄弟姪無干並未曾重張曲當情弊如有來歷不明係天釗出頭承當鄭家無涉到後帮葬花紅一概全免兩相允諾各毋反悔今啟有憑立送字永遠墳地契壙帛為據民國貳拾年春初立送字高天釗在見兄居碑誌代筆經手人族姪信釗代筆人
A8: 31735064607470_001 | B8: 31735064607470 | C8: 1 | D8: 1887 | E8: 1887 | F8: =IF(D8="","?",IF(D8<1796,"pre-1796",IF(D8<1912,"1796-1911",IF(D8<1949,"1912-1948","1949+")))) -> 1796-1911 | G8: =IF(D8="","?",IF(D8<1912,"Qing",IF(D8<1949,"Republic","PRC"))) -> Qing | H8: 1887 | I8: 閩侯（閩縣・侯官・林森） | J8: 福建省閩縣 | K8: Personal | M8: 王錦發 | N8: 王錦枝 | O8: Box 2, Folder 63 | P8: Private deed | Q8: 立賣斷契 | R8: 光緒拾叁年 | S8: 王錦發 | U8: 價錠銀柒拾伍兩正 | W8: 閩邑橫山鋪秋龍社 | Y8: 地基; 店屋 | Z8: 賣斷與堂兄; 林細弟 | AA8: 李逢銓 | AB8: 堂兄 | AC8: 母 林氏 | AI8: 1 | AJ8: 1 | AK8: 1 | AL8: 1 | AM8: 1 | AN8: 1 | AO8: 1 | AP8: 0 | AQ8: 1 | AR8: 1 | AS8: 1 | AT8: 0 | AU8: 0 | AV8: 0 | AW8: 0 | AX8: 0 | AY8: 0 | AZ8: 0 | BA8: 0 | BB8: 0 | BC8: 394 | BD8: 0 | BE8: 0 | BF8: 0 | BG8: https://digital.library.pitt.edu/islandora/object/pitt:31735064607470 | BH8: 立賣斷契王錦發原祖遺闔分份下有肆柱店面右半半內門窓戶榻前榻板地棚一切俱全坐產閩邑橫山鋪秋龍社地方前至官街後王清官屋在左邊錦枝半內店右至何家店上至掾桁磚瓦下至廊石礫石地基地陸至俱載明白今因要用情願將此右邊店面半內託中友賣斷與堂兄錦枝處永遠為業三面言議本日賣斷得店屋價錠銀柒拾伍兩正庫砵大錠白足色足兌其銀即日隨契親手收足其右邊半內店屋即所堂兄錦枝永遠管業千秋或自己居住或召租他人或折毀改式起蓋聽從其便係錦發自斷之後價足心願永斷葛藤向後永不敢言贖言湊言盡亦不敢別生枝節索取花紅之理但此店屋右半內係錦發祖遺闔分份下物業與親疎房份伯叔兄弟侄等無干亦未曾重張典當他人財物以及來歷不明各等情如有此情係錦發出頭抵當不涉堂兄之事兩相允愿各無翻悔今欲有憑立賣斷契事紙付執永遠為憑內併綴林春源典斷契司單下半屯相連標以知契母林氏光緒拾叁年冬月拾捌日立賣斷契王錦發胞弟森發在見堂兄俊發永發中友林細弟代筆李逢銓林春源
A9: 31735064607488_001 | B9: 31735064607488 | C9: 1 | D9: 1890 | E9: 1890 | F9: =IF(D9="","?",IF(D9<1796,"pre-1796",IF(D9<1912,"1796-1911",IF(D9<1949,"1912-1948","1949+")))) -> 1796-1911 | G9: =IF(D9="","?",IF(D9<1912,"Qing",IF(D9<1949,"Republic","PRC"))) -> Qing | H9: 1890 | I9: 閩侯（閩縣・侯官・林森） | J9: 福建省閩邑縣 | K9: Government | M9: 吳開成 | N9: 陳氏 | O9: Box 2, Folder 71 | P9: Private deed + state certificate | Q9: 立賣斷契 | R9: 同治玖年 | S9: 吳開成 | U9: 價銀陸拾捌兩正 | Y9: 厝屋 | Z9: 其屋式瑞數陸至俱; 李懷鏡 | AA9: 林枝三 | AB9: 親友陳清霖 | AC9: 嫂 洪氏 | AI9: 1 | AJ9: 0 | AK9: 1 | AL9: 0 | AM9: 1 | AN9: 1 | AO9: 1 | AP9: 0 | AQ9: 1 | AR9: 1 | AS9: 1 | AT9: 1 | AU9: 0 | AV9: 1 | AW9: 0 | AX9: 0 | AY9: 0 | AZ9: 0 | BA9: 0 | BB9: 0 | BC9: 551 | BD9: 0 | BE9: 0 | BF9: 0 | BG9: https://digital.library.pitt.edu/islandora/object/pitt:31735064607488 | BH9: 立賣斷契吳開成全姓瑞枝長庚原承祖遺下有厝屋肆在式欄相手座生產閩邑橫街舖地方前叁在門樓後引道至橫墻牆內左邊肆在屋後又有土庫肆在壹欄右邊肆在後又有拔水壹欄於道光貳拾叁年肆柒等年間經兄開揚在日憑中立典契先後曲在陳前魏各姓處為業緣年限已滿今因宗房別置全姪枝等向陳鄭魏邀往現繳典主劉李鄭各姓贖回隨托中友其屋式瑞數陸至俱載在贖回契內明白憑中統賣斷契陳處永遠為業三言議賣斷出屋價銀陸拾捌兩正庫大銀四其銀即日經成等隨契收足其厝屋即聽陳家永為子孫世業掌管收租或自己居住悉從其便成與枝等原價收足時價過浮自賣之後價足心願永斷萬無嗣後不得言贖言奉言盡之理以及別生枝等此屋緣因年久損壞倘陳家所毀改式起蓋聽從其便亦不敢啓齒索取花紅等情如有此情係成與枝等事但此厝屋係承祖遺下物業與親疎房份伯叔兄弟姪無亦未曾重張典當他人財物以及來歷不明各等情如有此情係成與枝等出頭承當不涉陳家之事兩相允願各無反悔今欲有過立賣斷契壹紙併繳陳家贖回契壹紙目壹紙鄭家贖回契壹紙魏家贖回契壹紙向陳家借字壹紙陳世旺繳典契壹紙鄭茂城繳典契壹紙魏振發繳典契壹紙劉嘉茂繳典契壹紙吳標標典契壹紙上年原曲斷契併司單執照老契壹拾肆紙共成貳拾伍紙統付永遠為憑知契嫂洪氏陳氏同治玖年十二月吉日賣斷契吳開成全姓瑞枝長庚全姪瑞枝長庚左見親友陳清霖中友李懷鏡代筆林枝三該契已協之永遠
A10: 31735064607496_001 | B10: 31735064607496 | C10: 1 | D10: 1900 | E10: 1900 | F10: =IF(D10="","?",IF(D10<1796,"pre-1796",IF(D10<1912,"1796-1911",IF(D10<1949,"1912-1948","1949+")))) -> 1796-1911 | G10: =IF(D10="","?",IF(D10<1912,"Qing",IF(D10<1949,"Republic","PRC"))) -> Qing | H10: 1900 | I10: 閩侯（閩縣・侯官・林森） | J10: 福建省閩邑縣 | K10: Government | M10: 鄒允春 | N10: 和意軒老人會 | O10: Box 2, Folder 82 | P10: Private deed | Q10: 立賣斷契 | R10: 光緒貳拾陸年 | S10: 鄒允春 | T10: 和意軒老人會 | U10: 價庫平銀肆拾肆兩正 | V10: 庫平 | Y10: 厝屋; 地基 | Z10: 王伊細 | AA10: 李松軒謹 | AB10: 表弟黃公弼 | AI10: 1 | AJ10: 0 | AK10: 1 | AL10: 1 | AM10: 1 | AN10: 1 | AO10: 1 | AP10: 0 | AQ10: 1 | AR10: 1 | AS10: 1 | AT10: 0 | AU10: 0 | AV10: 1 | AW10: 0 | AX10: 0 | AY10: 0 | AZ10: 0 | BA10: 0 | BB10: 0 | BC10: 336 | BD10: 1 | BE10: 0 | BF10: 0 | BG10: https://digital.library.pitt.edu/islandora/object/pitt:31735064607496 | BH10: 立賣斷契鄒允春承父手置原有厝屋叁柱式欄排串座共成式堵上有標椽磚瓦上至天至天下至地基地礫石地地內有門窓戶榻地坪板榻一切俱全橫濶式丈式尺參直深式丈肆尺參左至鄭家屋右至鄭家簷坪後至蘓家墻六至俱俱明白厝角水井通用座產閩邑嘉崇里文山舖秋龍社地方今因要托中賣斷與和意軒老人會處永遠為業本日三面言議賣斷得厝價庫平銀肆拾肆兩正即日隨契收足其屋所憑買主或自己居住或租他人悉從其便春自賣之後價足心願永斷葛藤但此屋係父自己手置與親疎伯叔兄弟侄無干並未曾重張典當他人財物之理以及來歷不明各等情如有此情係春出頭承當與買主無涉之事不得異說各無反悔今欲有憑立賣斷契事紙並張銓銓原契事紙司單事紙共成叁紙付執為憑內標註至用式字為憑在見表弟黃公弼光緒貳拾陸年閏捌月吉日立賣斷契鄒允春中人王伊細代筆李松軒謹卷八
A11: 31735064607504_001 | B11: 31735064607504 | C11: 1 | D11: 1918 | E11: 1918 | F11: =IF(D11="","?",IF(D11<1796,"pre-1796",IF(D11<1912,"1796-1911",IF(D11<1949,"1912-1948","1949+")))) -> 1912-1948 | G11: =IF(D11="","?",IF(D11<1912,"Qing",IF(D11<1949,"Republic","PRC"))) -> Republic | H11: 1918 | I11: 閩侯（閩縣・侯官・林森） | J11: 福建省閩侯縣 | K11: Government | M11: 陳燦祥 | N11: 吳 | O11: Box 2, Folder 108 | P11: Private deed + state certificate | Q11: 立契 | R11: 民國六年; 中華民國七年 | U11: 價柒百元 | V11: 大洋 | W11: 橫街舖茶葉衙面積壹庄一不動產之買 | Z11: 吳維清 | AE11: 典 契 | 例 則 摘 要 | AI11: 0 | AJ11: 0 | AK11: 0 | AL11: 0 | AM11: 0 | AN11: 0 | AO11: 0 | AP11: 0 | AQ11: 0 | AR11: 0 | AS11: 1 | AT11: 1 | AU11: 0 | AV11: 0 | AW11: 0 | AX11: 0 | AY11: 0 | AZ11: 0 | BA11: 1 | BB11: 1 | BC11: 605 | BD11: 0 | BE11: 0 | BF11: 0 | BG11: https://digital.library.pitt.edu/islandora/object/pitt:31735064607504 | BH11: 典契例則摘要承典人姓名吳不動產種類牆屋典價柒百元應納稅額貳拾壹元原契幾張立契年月日民國六年十二月四至北至西至南至東至坐落橫街舖茶葉衙面積壹庄一不動產之買主或承典人須於契紙成立後六個月以內赴該管徵收官署投稅一訂立不動產買契或典契時須由賣主或出典人赴該管徵收官署填具申請書請領契紙繳納契紙費大洋五角前項之契紙費五角由賣主與買主或出典人與承典人分擔一不動產之賣主或出典人請領契紙後已逾兩月其契約尚未成立者原領契紙失其効力但因有障礙致契約不能成立時得於限內赴徵收官署申明事由酌予寬限一原領契紙因遺失及其他事由須補領或更換時仍依第四條第一項之規定繳納契紙費一不動產之買主或承典人逾契約成立後六個月之期限不依本條例繳納契稅者除約定稅之稅額外並處以應納稅額之十倍罰金一繳納契稅時匿稅契價者除另換契紙改正契約繳納稅額外並處以左列之罰金一匿報契價十分之二以上未滿十分之三者短納稅額之二倍一匿報契價十分之三以上未滿十分之四者短納稅額之四倍一匿報契價十分之四以上未滿十分之五者短納稅額之八倍一匿報契價十分之五以上者短納稅額之十六倍或由徵稅官署依所報契價收買之一契約成立後六個月之納稅期間限於遵領官契紙者適用之其私紙所書之契約若事後不換寫契紙以逾限論一賣主或出典人以私紙訂立契約者得由徵稅官署處以五元以上五十元以下之罰金一逾限未稅之契訴訟時無憑證之效力中華民國七年四月廿六日出典人陳燦祥中人吳維清繕契核對陶筱泉縣給留字第虎完兌限合壹元
A12: 31735064607512_001 | B12: 31735064607512 | C12: 1 | D12: 1924 | E12: 1924 | F12: =IF(D12="","?",IF(D12<1796,"pre-1796",IF(D12<1912,"1796-1911",IF(D12<1949,"1912-1948","1949+")))) -> 1912-1948 | G12: =IF(D12="","?",IF(D12<1912,"Qing",IF(D12<1949,"Republic","PRC"))) -> Republic | H12: 1924 | I12: 閩侯（閩縣・侯官・林森） | J12: 福建省閩侯縣 | K12: Government | M12: 王三妹 | N12: 陳軍漢 | O12: Box 3, Folder 119 | P12: Private deed | Q12: 立典屋契 | S12: 約王三妹 | T12: 陳軍漢 | U12: 伏壹佰式拾伍元正; 銀台伏壹佰叁拾伍元 | V12: 台伏 | W12: 福州閩侯縣轄內文山鋪秋龍社下底埕 | Y12: 地基 | Z12: 林武欽 | AD12: 五 | AI12: 1 | AJ12: 0 | AK12: 0 | AL12: 1 | AM12: 1 | AN12: 1 | AO12: 1 | AP12: 1 | AQ12: 0 | AR12: 1 | AS12: 1 | AT12: 1 | AU12: 0 | AV12: 0 | AW12: 0 | AX12: 0 | AY12: 0 | AZ12: 0 | BA12: 0 | BB12: 0 | BC12: 356 | BD12: 0 | BE12: 0 | BF12: 0 | BG12: https://digital.library.pitt.edu/islandora/object/pitt:31735064607512 | BH12: 立典屋契約王三妹承繼父遺下有民屋一所坐產福州閩侯縣轄內文山鋪秋龍社下底埕地方坐北向南其屋式柱一欄前至天井後至牆左至廊墘右至王家上至椽瓦天下至地基地左邊房屋一堵右邊廊墘一堵共成參堵門牌戶嫡及椽極地秤破舊畧全今因要需於中將該屋典與陳軍漢處為業三面議定典價銀台伏壹佰式拾伍元正又貼修理費壹拾元合共貳大壹佰叁拾伍元正其銀即日經中收足其屋即聽陳處掌管或已居住或租他人均從其便約定五年為限期滿之日聽妹籌備原典銀台伏壹佰叁拾伍元取贖不得半途言贖及別生枝節但此屋係妹繼父遺產與親疏所伯叔兄弟姪等無關亦未曾重張典當他人財物如有來應不明係妹出頭承當不涉與之事若遇天災時變兩家均分各半雙方允諾各無反悔今設有憑蓋屋契約一紙並繳王齊發契一紙共應式紙統付為據此照標明郭宗付老原契遺失中人林武欽王斌斌知契生父王繼保立典屋契約卷之二文山鋪秋龍巷
A13: 31735064607512_002 | B13: 31735064607512 | C13: 2 | D13: 1924 | E13: 1924 | F13: =IF(D13="","?",IF(D13<1796,"pre-1796",IF(D13<1912,"1796-1911",IF(D13<1949,"1912-1948","1949+")))) -> 1912-1948 | G13: =IF(D13="","?",IF(D13<1912,"Qing",IF(D13<1949,"Republic","PRC"))) -> Republic | H13: 1924 | I13: 閩侯（閩縣・侯官・林森） | J13: 福建省閩侯縣 | K13: Government | M13: 王三妹 | N13: 陳軍漢 | O13: Box 3, Folder 119 | P13: Official form | Q13: 立契 | R13: 民國十三年 | U13: 價壹百貳拾伍元 | Y13: 厝屋 | AE13: 典 | AI13: 0 | AJ13: 0 | AK13: 0 | AL13: 0 | AM13: 0 | AN13: 0 | AO13: 0 | AP13: 0 | AQ13: 0 | AR13: 0 | AS13: 0 | AT13: 1 | AU13: 0 | AV13: 0 | AW13: 0 | AX13: 0 | AY13: 0 | AZ13: 0 | BA13: 0 | BB13: 1 | BC13: 171 | BD13: 0 | BE13: 0 | BF13: 0 | BG13: https://digital.library.pitt.edu/islandora/object/pitt:31735064607512 | BH13: 第典李契銀每張收善附捐壹元相第張卷承典人姓名陳軍漢不動產種類厝屋典價壹百貳拾伍元應納稅額叁元柒角伍占原契幾張立契年月日民國十三年二月到坐面落文山鋪秋龍巷積貳拾壹元四至東至南至西至北至清查一不動產之買主或承典人須於契紙成立後六個月以內赴該管徵收官署投稅二出典人赴該管徵收官署填具申請書請領契紙三立者原領契紙失其效力但寬限四繳納契紙費五首余酌定稅
A14: 31735064607520_001 | B14: 31735064607520 | C14: 1 | D14: 1876 | E14: 1876 | F14: =IF(D14="","?",IF(D14<1796,"pre-1796",IF(D14<1912,"1796-1911",IF(D14<1949,"1912-1948","1949+")))) -> 1796-1911 | G14: =IF(D14="","?",IF(D14<1912,"Qing",IF(D14<1949,"Republic","PRC"))) -> Qing | H14: 1876 | I14: 永安 | J14: 福建省永安縣 | K14: Government | M14: 祿中 | O14: Box 2, Folder 55 | P14: Private deed | Q14: 立杜賣田皮骨契 | R14: 光緒二年 | S14: 祿中客 | U14: 價銀壹拾柒員正 | Y14: 田皮 | AA14: 海中客 | AB14: 見代筆人海中客 | AI14: 1 | AJ14: 0 | AK14: 1 | AL14: 1 | AM14: 1 | AN14: 0 | AO14: 0 | AP14: 0 | AQ14: 1 | AR14: 0 | AS14: 1 | AT14: 0 | AU14: 0 | AV14: 0 | AW14: 0 | AX14: 0 | AY14: 0 | AZ14: 0 | BA14: 0 | BB14: 0 | BC14: 246 | BD14: 1 | BE14: 0 | BF14: 0 | BG14: https://digital.library.pitt.edu/islandora/object/pitt:31735064607520 | BH14: 立杜賣田皮骨契字人祿中今因少銀使用即將父分閩下禾田土名下屋仔虎形地堂下塘仔禾田一坵欲行出賣前來向到本家吉昌兄出首承買即日憑中三面時值盡骨併帶飯糧花押酒席一應在內共成六兌價銀壹拾柒員正其係隨字交付足額載今邑民未陸合其田自賣之後任憑賣主過手會業耕作其糧米任憑過割入冊有賣人叔侄兄弟不得添事等情此係正行交易不是負債準折之故價盡未足永無後贖恐口無憑立杜賣田皮骨契字一紙付與買主收執永遠為據即日收到字內畫骨田價銀壹拾柒員正俱收足記在場見代筆人海中客在堂母氏蘇光緒二年丙子歲十月廿七日立杜賣畫田字人祿中客
A15: 31735064607538_001 | B15: 31735064607538 | C15: 1 | D15: 1761 | E15: 1762 | F15: =IF(D15="","?",IF(D15<1796,"pre-1796",IF(D15<1912,"1796-1911",IF(D15<1949,"1912-1948","1949+")))) -> pre-1796 | G15: =IF(D15="","?",IF(D15<1912,"Qing",IF(D15<1949,"Republic","PRC"))) -> Qing | H15: 1761/1762 | I15: 永定 | J15: 福建省永定縣 | K15: Government | M15: 許瓊栢 | N15: 吳省忠 | O15: Box 1, Folder 5 | P15: Other / fragment | Q15: 立賣買山埔土審契 | R15: 乾隆貳拾六年 | S15: 許瓊相 | U15: 銀九四星色叁拾兩正; 價銀叁拾兩正 | W15: 大溪邊礫下崗上原有土審貳穴上至許 | Y15: 山埔; 墳 | AI15: 0 | AJ15: 0 | AK15: 1 | AL15: 0 | AM15: 1 | AN15: 0 | AO15: 0 | AP15: 0 | AQ15: 1 | AR15: 1 | AS15: 1 | AT15: 0 | AU15: 0 | AV15: 0 | AW15: 0 | AX15: 0 | AY15: 0 | AZ15: 0 | BA15: 0 | BB15: 0 | BC15: 335 | BD15: 3 | BE15: 0 | BF15: 0 | BG15: https://digital.library.pitt.edu/islandora/object/pitt:31735064607538 | BH15: 立賣買山埔土審契人許瓊相學明利錫今有祖父遺下山埔壹所坐落大溪邊礫下崗上原有土審貳穴上至許家墳下為界下至圳面為界左右並無土審相連其山埔內上下左右并土審貳穴欲行出賣前來托中送與吳省忠叔姪等出首承買當日憑中三向言斷時值山埔土審價銀九四星色叁拾兩正其銀即日隨契交訖不欠分文自的筆之日其大溪邊礫下崗上埔壹所共土審貳穴從吳省忠叔姪等前去堆砌土築板安置遷上遷下遷左遷右有許瓊相兄弟叔姪貳房等不得異言阻當等情其山埔土審與房族叔伯兄弟人等並無寸土干涉亦不會重複典當他人財物委係正行交易不是負債推折之故今欲有憑立賣買山埔土審契永遠為照即日得收山埔土審契內價銀叁拾兩正足訖說命人官盛清務房戶許芳相等乾隆貳拾六年辛巳歲拾月初二日立賣買山埔土審契人許瓊相北相瓊相或相字全姪信上利盛與平明聯上兩北上
A16: 31735064607538_002 | B16: 31735064607538 | C16: 2 | D16: 1761 | E16: 1762 | F16: =IF(D16="","?",IF(D16<1796,"pre-1796",IF(D16<1912,"1796-1911",IF(D16<1949,"1912-1948","1949+")))) -> pre-1796 | G16: =IF(D16="","?",IF(D16<1912,"Qing",IF(D16<1949,"Republic","PRC"))) -> Qing | H16: 1761/1762 | I16: 永定 | J16: 福建省永定縣 | K16: Government | M16: 許瓊栢 | N16: 吳省忠 | O16: Box 1, Folder 5 | P16: Official form | R16: 乾隆十五年; 乾隆貳拾柒年 | AE16: 欽 | AF16: 福建等處承宣布政使司 | AI16: 0 | AJ16: 0 | AK16: 0 | AL16: 0 | AM16: 0 | AN16: 0 | AO16: 0 | AP16: 0 | AQ16: 0 | AR16: 0 | AS16: 0 | AT16: 0 | AU16: 0 | AV16: 0 | AW16: 1 | AX16: 1 | AY16: 0 | AZ16: 0 | BA16: 0 | BB16: 0 | BC16: 742 | BD16: 3 | BE16: 0 | BF16: 0 | BG16: https://digital.library.pitt.edu/islandora/object/pitt:31735064607538 | BH16: 欽永字一千四百十三號福建等處承宣布政使司為查據奏事乾隆十五年正月二十四日奉准戶部咨開司案呈所有奉部議覆河南布政使高爾隆奏買賣田產將契尾精連用印存貯申送府州藩司查驗等因一摺于本年十一月二十二日奉本日來查依議欽此相應抄錄原奏并頒發格式行文福憲照欽遵辦理可也計前單一紙格式一張內開該府等查得該布政使高爾隆奏稱部議多頒契尾以後巧取病民緣象勢難免例不與照根契中上已查驗不自備其與給民契尾則按數登與而于存官照根或將價銀刪改請照後州縣于票之納照時符即將應給集戶之契尾并州縣備案之照根等項從未議將花戶收執票與申繳上司收執等項與照根并送查發是難項更難于正賦稅與照根且當緣為奸情勒索查以致難戶經年累月求其難望其掛圖匿白契而不解不目誤費集照根而直隸州照州縣例例送照用之處均毋庸議至請嗣後布政司頒發給民契尾格式編列號數前中印鈐司印以備投稅時將契價稅銀數目太字與票和政司查核此係一行筆跡平分為二大小數目妥離子虞而契價無參差之契于民無累于稅無虧侵舒杜爭訟可息矣如蒙照其契尾一項經二衙門即多一衙門之停關由吏胥即多一吏胥之索索甚亦以憑票請州縣經收稅銀將契尾粘連存貯一單中送府州官照根而直隸吏以大細小奸民爭執訂訟定緣法久弊生不可不事為變通自應將照常細畫業戶等姓名買賣田房數目價銀稅銀若干後半幅下空白處印之處令業戶看明當面騎字截開將幅將業戶及執後幅司印冊景換其稅前州縣布政司銷送各契尾應將停止以省繁文庶契尾無停爭訟可息矣如蒙命下之日部頒發格式通行無有督撫一體欽遵謹此等因咨院行司奉此納稅銀玖錢五納稅銀玖錢五納稅銀玖錢五納稅銀玖錢五納稅銀玖錢五納稅銀玖錢五納稅銀玖錢五納稅銀玖錢五納稅銀玖錢五納稅銀玖錢五納稅銀玖錢五納稅銀玖錢五納稅銀玖錢五納稅銀玖錢五納稅銀玖錢五乾隆貳拾柒年捌月永字壹千肆百八拾號白給永茂縣葉口吳有德佳此
A17: 31735064607546_001 | B17: 31735064607546 | C17: 1 | D17: 1760 | E17: 1767 | F17: =IF(D17="","?",IF(D17<1796,"pre-1796",IF(D17<1912,"1796-1911",IF(D17<1949,"1912-1948","1949+")))) -> pre-1796 | G17: =IF(D17="","?",IF(D17<1912,"Qing",IF(D17<1949,"Republic","PRC"))) -> Qing | H17: 1760/1767 | I17: 閩清 | J17: 福建省閩清縣 | K17: Government | L17: 黃毓扆 | O17: Box 1, Folder 4 | P17: Private deed | Q17: 立典契 | R17: 乾隆貳拾伍年 | S17: 黃毓辰 | T17: 葉 | U17: 價銀陸拾叁兩正 | W17: 檢壹都 | Y17: 民田 | Z17: 薛宜章 | AB17: 劉有臺 | AI17: 1 | AJ17: 0 | AK17: 1 | AL17: 0 | AM17: 1 | AN17: 1 | AO17: 0 | AP17: 1 | AQ17: 0 | AR17: 0 | AS17: 1 | AT17: 0 | AU17: 0 | AV17: 0 | AW17: 0 | AX17: 0 | AY17: 0 | AZ17: 0 | BA17: 0 | BB17: 0 | BC17: 341 | BD17: 1 | BE17: 0 | BF17: 0 | BG17: https://digital.library.pitt.edu/islandora/object/pitt:31735064607546 | BH17: 立典契黃毓辰承祖有民田數號坐產檢壹都地方土名和尚壠長壠平水潭台尾上下大坵尾園前後埭埭利吳晉洋上中假桑園二小坵等處受種伍斗陸升伍合年載租米伍碩陸伍升伍合斗陸升伍合立在昇平文親孝仁戶下今因乏用托中典與葉處為葉三向言議得訖田價銀陸拾叁兩正紋廣其銀即日收足其田轉銀主前去會佃收租自是身苗糧聽從葉過割入戶西約伍年限滿之日借銀以契面銀兩定期取贖葉不得自留此田係自己物業與別房佃叔兄等無干上上本自重張典當他人財物如有未磨不明係辰出欵抵當不得借銀主事今欲有洗立典契為憑此為計開一個陳朝彩出名和尚壠載租米壹石捌斗官姓李長一個許維實出名長壠平水潭台尾抽出租米壹石捌斗官一個林子為土名上下大坵尾園前徐假埭利吳晉洋上中假桑園二小坵載租米貳石柒斗官乾隆貳拾伍年伍月立典契黃毓辰中人薛宜章左見劉有臺謝朝尊謹大壠
A18: 31735064607546_002 | B18: 31735064607546 | C18: 2 | D18: 1760 | E18: 1767 | F18: =IF(D18="","?",IF(D18<1796,"pre-1796",IF(D18<1912,"1796-1911",IF(D18<1949,"1912-1948","1949+")))) -> pre-1796 | G18: =IF(D18="","?",IF(D18<1912,"Qing",IF(D18<1949,"Republic","PRC"))) -> Qing | H18: 1760/1767 | I18: 閩清 | J18: 福建省閩清縣 | K18: Government | L18: 黃毓扆 | O18: Box 1, Folder 4 | P18: Private deed | Q18: 立湊字 | R18: 乾隆叁拾貳年 | S18: 黃毓辰原 | Y18: 民田; 苗米; 田面 | Z18: 列有炳燧 | AI18: 0 | AJ18: 0 | AK18: 1 | AL18: 0 | AM18: 1 | AN18: 0 | AO18: 0 | AP18: 0 | AQ18: 0 | AR18: 0 | AS18: 0 | AT18: 0 | AU18: 0 | AV18: 0 | AW18: 0 | AX18: 0 | AY18: 0 | AZ18: 0 | BA18: 0 | BB18: 0 | BC18: 127 | BD18: 0 | BE18: 0 | BF18: 0 | BG18: https://digital.library.pitt.edu/islandora/object/pitt:31735064607546 | BH18: 立湊字黃毓辰子前耳向有民田數號其理名銀西土名苗米俱載草契內明白若因立用托中向立葉表伯處湊出制鈔書拉子又石其鈔即日收其其田面約再限出仁耳備年之日以原湊專銀西取燒如未取燒契聽從以四收葉立湊字葉弟併原契其成或命助乃乾隆叁拾貳年伍月日立湊字黃毓辰原契中見列有炳燧
A19: 31735064607553_001 | B19: 31735064607553 | C19: 1 | D19: 1940 | E19: 1940 | F19: =IF(D19="","?",IF(D19<1796,"pre-1796",IF(D19<1912,"1796-1911",IF(D19<1949,"1912-1948","1949+")))) -> 1912-1948 | G19: =IF(D19="","?",IF(D19<1912,"Qing",IF(D19<1949,"Republic","PRC"))) -> Republic | H19: 1940 | K19: Personal | M19: 藍維乾 | 藍維坤 | N19: 吳淮棉 | O19: Box 3, Folder 162 | P19: Private deed | Q19: 立令賣契 | S19: 要藍維坤 | U19: 幣銀書佰壹拾員正 | V19: 國幣 | Z19: 抵當不涉銀主之事; 吳淮西 | AA19: 陳鳳英 | AB19: 龍叔世錄 | AI19: 0 | AJ19: 0 | AK19: 1 | AL19: 1 | AM19: 1 | AN19: 0 | AO19: 1 | AP19: 1 | AQ19: 1 | AR19: 1 | AS19: 1 | AT19: 0 | AU19: 0 | AV19: 1 | AW19: 0 | AX19: 0 | AY19: 0 | AZ19: 0 | BA19: 0 | BB19: 0 | BC19: 297 | BD19: 1 | BE19: 0 | BF19: 1 | BG19: https://digital.library.pitt.edu/islandora/object/pitt:31735064607553 | BH19: 立令賣契藍維坤原史手闕於下有山國書號坐地本山土名定下坑大小坑近載藤書千伍佰餘根東至淮球國為界西至立善園為界南至淮元田為界北至土墓為界於立以少令因要用托中引引吳淮棉處三面言說賣契以示國所國幣銀書佰壹拾員正其銀即日親手收足其山國即付銀主壹壹名佃他人耕作栽種地依此山國係坤原史手闕於下有立業為本房內諸人等於子並未重此典當他人財物中有不以唯坤原史手已出頭令中見抵當不涉銀主之事自賣契以後永為銀主久遠實業與坤原史手孫半點無干園內有吉穴聽從銀主擇吉這並不敢言說取贖說契契膠貼易生枝節之理此乃係足心願各勿反悔今致有憑立賣契契書序為據在見龍叔世錄中華民國庚辰年拾月吉日立賣契要藍維坤坤原史手中人吳淮西代筆陳鳳英
A20: 31735064607561_001 | B20: 31735064607561 | C20: 1 | D20: 1917 | E20: 1917 | F20: =IF(D20="","?",IF(D20<1796,"pre-1796",IF(D20<1912,"1796-1911",IF(D20<1949,"1912-1948","1949+")))) -> 1912-1948 | G20: =IF(D20="","?",IF(D20<1912,"Qing",IF(D20<1949,"Republic","PRC"))) -> Republic | H20: 1917 | K20: Personal | M20: 維衜 | O20: Box 2, Folder 105 | P20: Private deed | Q20: 立賣斷契 | S20: 贈侄孫維 | U20: 價番銀貳拾柒員正 | V20: 番銀 | W20: 本增墾頭 | AA20: 中陳端率 | AB20: 胞弟 | AI20: 1 | AJ20: 0 | AK20: 1 | AL20: 0 | AM20: 1 | AN20: 1 | AO20: 1 | AP20: 1 | AQ20: 1 | AR20: 1 | AS20: 1 | AT20: 0 | AU20: 0 | AV20: 0 | AW20: 0 | AX20: 0 | AY20: 0 | AZ20: 0 | BA20: 0 | BB20: 0 | BC20: 295 | BD20: 0 | BE20: 0 | BF20: 0 | BG20: https://digital.library.pitt.edu/islandora/object/pitt:31735064607561 | BH20: 立賣斷契贈侄孫維衡原祖上遺下有茄種園雲驛坐址本增墾頭土名竹籃下雲坵載籐書千伍百餘根西至路為界東至青元茄種園為界南至良良園為界北至現為界肆至明白今因要用托中引到贈叔祖公勳懷諸面議賣斷得出價番銀貳拾柒員正每員陸份捌分重其銀即日親手收足其茄種園聽從贈叔祖管業召佃耕作栽種地瓜此茄種園係原祖上遺下實業由本房內諸人無干並未重張典當他人財中有不明係自行抵當不涉贈叔祖之事自賣斷以後永為贈叔祖久遠實業由半點絲毫無干如有因內吉穴聽從贈叔祖擇吉起蓋並不敢言說取贖贖貼另生枝節之理此乃價足心愿各無反悔今故有憑立賣斷契書紙為據在見胞弟維壽維炎從命男長善中華民國丁巳陸年拾月廿日立賣斷契贈侄孫維衡代筆中陳端率禮大和
A21: 31735064607579_001 | B21: 31735064607579 | C21: 1 | D21: 1805 | E21: 1816 | F21: =IF(D21="","?",IF(D21<1796,"pre-1796",IF(D21<1912,"1796-1911",IF(D21<1949,"1912-1948","1949+")))) -> 1796-1911 | G21: =IF(D21="","?",IF(D21<1912,"Qing",IF(D21<1949,"Republic","PRC"))) -> Qing | H21: 1805/1816 | I21: 閩侯（閩縣・侯官・林森） | J21: 福建省閩縣 | K21: Government | L21: 吳秉鑒 | M21: 吳秉鑒 | N21: 謝先經 | O21: Box 1, Folder 16 | P21: Private deed | Q21: 立轉典契 | R21: 嘉慶十年 | S21: 吳秉鑄 | Z21: 鄭長梅 | AC21: 王氏 | AI21: 0 | AJ21: 0 | AK21: 0 | AL21: 0 | AM21: 0 | AN21: 0 | AO21: 0 | AP21: 0 | AQ21: 0 | AR21: 0 | AS21: 0 | AT21: 0 | AU21: 0 | AV21: 0 | AW21: 0 | AX21: 0 | AY21: 0 | AZ21: 0 | BA21: 0 | BB21: 0 | BC21: 46 | BD21: 2 | BE21: 0 | BF21: 0 | BG21: https://digital.library.pitt.edu/islandora/object/pitt:31735064607579 | BH21: 嘉慶十年六月吉大見卷知契王氏日立轉典契吳秉鑄胞弟秉鈞中見鄭長梅金存國鄭捷登秉筆林學經鄭保涂正
A22: 31735064607579_002 | B22: 31735064607579 | C22: 2 | D22: 1805 | E22: 1816 | F22: =IF(D22="","?",IF(D22<1796,"pre-1796",IF(D22<1912,"1796-1911",IF(D22<1949,"1912-1948","1949+")))) -> 1796-1911 | G22: =IF(D22="","?",IF(D22<1912,"Qing",IF(D22<1949,"Republic","PRC"))) -> Qing | H22: 1805/1816 | I22: 閩侯（閩縣・侯官・林森） | J22: 福建省閩縣 | K22: Government | L22: 吳秉鑒 | M22: 吳秉鑒 | N22: 謝先經 | O22: Box 1, Folder 16 | P22: Other / fragment | AI22: 0 | AJ22: 0 | AK22: 0 | AL22: 0 | AM22: 0 | AN22: 0 | AO22: 0 | AP22: 0 | AQ22: 0 | AR22: 0 | AS22: 0 | AT22: 0 | AU22: 0 | AV22: 0 | AW22: 0 | AX22: 0 | AY22: 0 | AZ22: 0 | BA22: 0 | BB22: 0 | BC22: 1 | BD22: 1 | BE22: 0 | BF22: 0 | BG22: https://digital.library.pitt.edu/islandora/object/pitt:31735064607579 | BH22: 契
A23: 31735064607587_001 | B23: 31735064607587 | C23: 1 | D23: 1871 | E23: 1913 | F23: =IF(D23="","?",IF(D23<1796,"pre-1796",IF(D23<1912,"1796-1911",IF(D23<1949,"1912-1948","1949+")))) -> 1796-1911 | G23: =IF(D23="","?",IF(D23<1912,"Qing",IF(D23<1949,"Republic","PRC"))) -> Qing | H23: 1871/1913 | I23: 閩侯（閩縣・侯官・林森） | J23: 福建省閩侯縣 | K23: Government | M23: 方元慈 | N23: 方潮濤 | O23: Box 1, Folder 50 | P23: Private deed + state certificate | Q23: 立賣斷根面全田契 | R23: 中華民國 年; 中華民國 11 年; 同治拾年 | S23: 第方元慈 | U23: 價一千五百元; 價銀壹百壹拾元正 | W23: 二號不動產面積二畝四至東至南至西 | Y23: 根面全田 | Z23: 族叔 | AA23: 魏佳 | AB23: 母親 | AC23: 嫂 趙氏 | AE23: 單 契 斷 賣 | 福建省政府財政廳頒發閩侯縣已稅契驗契證 | AF23: 福建省政府財政廳 | AG23: 業戶; 住址 | AI23: 1 | AJ23: 0 | AK23: 1 | AL23: 0 | AM23: 1 | AN23: 1 | AO23: 0 | AP23: 0 | AQ23: 1 | AR23: 1 | AS23: 1 | AT23: 0 | AU23: 0 | AV23: 1 | AW23: 0 | AX23: 0 | AY23: 0 | AZ23: 1 | BA23: 0 | BB23: 0 | BC23: 676 | BD23: 2 | BE23: 0 | BF23: 1 | BG23: https://digital.library.pitt.edu/islandora/object/pitt:31735064607587 | BH23: 單契斷賣中華民國年拾壹月卷拾日拾證方濃官原價銀紙價實銀兩共已如數收訖西至北至坐向橫丈尺直丈尺中東水湯北督催處右給業戶潮青准此福建省政府財政廳頒發閩侯縣已稅契驗契證茲為整理契稅，體卹人民，保障產權起見，特定驗契辦法，凡屬田園屋地各類不動產，已稅未稅契據，均應一律投驗，填給驗契證，已稅之紅契，不收驗費，未稅之白契，無論典賣及產價多寡，每張祇收驗契費銀壹元，短此驗契，粘有驗契證者，方為有效。非經買賣轉移，不再徵稅。業主姓名潮青業主住址閩侯不動產種類田不動產坐落二號不動產面積二畝四至東至南至西至北至畝分契分契等則賦額地丁糧米產價一百一十五千六業主姓名潮青中人姓名潮青契價一千五百元其他此契係1917年11月11日人此處蓋財政廳驗契證開份此處蓋財政廳驗契證開份此處蓋財政廳驗契證開份中華民國11年11月11日第41740號此種已稅契驗契證收驗費閩侯縣三此張填給業主粘連原契合業同治拾年拾壹月吉日立賣斷根面全田契第方元慈鑒代筆魏佳謹啟在見母親許氏嫂趙氏中人族叔濃官立賣斷根面全田契第方元慈原承父閩書份下有根面全田委原糧銀三十九部壹甲方道戶下又掛三十八部四圍八甲方福昌戶下又掛三十八部壹圍六甲方永平戶下銀照票例科繳應掌無異今因別置托中將此田統斷與兄潮青處永遠為業云云言議本日賣斷出田價銀壹百壹拾元正其錢即日全中收足其田即聽兄掌管新作定納糧色弟自賣斷之後價足心慰永斷萬無向後永不得用生枝即以此田係弟承父閩書份下為業與本別居親族人等無干亦未曾重張回當他人財物如有來應不係弟祇當與兄無干兩相允應各無反悔今欲有憑立賣斷根面全田契壹紙付現為照其憑契因洪水陸等朽腐無可徵付
A24: 31735064607587_002 | B24: 31735064607587 | C24: 2 | D24: 1871 | E24: 1913 | F24: =IF(D24="","?",IF(D24<1796,"pre-1796",IF(D24<1912,"1796-1911",IF(D24<1949,"1912-1948","1949+")))) -> 1796-1911 | G24: =IF(D24="","?",IF(D24<1912,"Qing",IF(D24<1949,"Republic","PRC"))) -> Qing | H24: 1871/1913 | I24: 閩侯（閩縣・侯官・林森） | J24: 福建省閩侯縣 | K24: Government | M24: 方元慈 | N24: 方潮濤 | O24: Box 1, Folder 50 | P24: Private deed | Q24: 立賣斷根面全田契 | R24: 同治拾年 | S24: 弟方元慈 | U24: 價錢壹百壹拾伍千文正 | W24: 侯邑三十九都 | X24: 圳仔墘 | Y24: 根面全田 | Z24: 族叔濃官 | AA24: 孫佳亨 | AB24: 母親許氏 | AC24: 母親許氏; 嫂趙氏 | AI24: 1 | AJ24: 0 | AK24: 1 | AL24: 1 | AM24: 1 | AN24: 1 | AO24: 0 | AP24: 0 | AQ24: 1 | AR24: 1 | AS24: 1 | AT24: 0 | AU24: 0 | AV24: 1 | AW24: 0 | AX24: 0 | AY24: 0 | AZ24: 0 | BA24: 0 | BB24: 0 | BC24: 346 | BD24: 3 | BE24: 0 | BF24: 0 | BG24: https://digital.library.pitt.edu/islandora/object/pitt:31735064607587 | BH24: 此立賣斷根面全田契弟方元慈原承父閭書份下有根面全田坐落侯邑三十九都地方土名圳仔墘田大小丞坊官犬式畝式分零糧掛三十九都壹甲方道戶下又掛三十八都四圖八甲方福昌戶下又掛三十八都壹圖六甲方永平戶下銀米照縣例科派應掌無異今因別置托中將此田統斷與兄潮壽處永遠為業三面言議本月賣斷出田價錢壹百壹拾伍千文正其錢即日全中收足其田即聽兄掌管耕作完納糧色弟自賣斷之後價足心慈永斷葛藤自後永不得別生枝節但此田係弟承父閭書份下物業與本別房親疎人等無干亦未曾重張曲當他人財物如有來應不係弟抵當與兄無干兩相允慈各無反悔今欲有憑立賣斷根面全田契壹紙付執為照其愿契因洪水陵厝朽腐無可徵付中人族叔濃官在見母親許氏嫂趙氏Handwrittensignatureormark.同治拾年拾壹月吉日立賣斷根面全田契弟方元慈代筆孫佳亨承林
A25: 31735064607587_003 | B25: 31735064607587 | C25: 3 | D25: 1871 | E25: 1913 | F25: =IF(D25="","?",IF(D25<1796,"pre-1796",IF(D25<1912,"1796-1911",IF(D25<1949,"1912-1948","1949+")))) -> 1796-1911 | G25: =IF(D25="","?",IF(D25<1912,"Qing",IF(D25<1949,"Republic","PRC"))) -> Qing | H25: 1871/1913 | I25: 閩侯（閩縣・侯官・林森） | J25: 福建省閩侯縣 | K25: Government | M25: 方元慈 | N25: 方潮濤 | O25: Box 1, Folder 50 | P25: Official form | Q25: 立之不動產舊契 | R25: 同治拾年; 中華民國 貳年 | U25: 價銀兩申銀壹百壹拾伍元 | V25: 銀元 | W25: 閩侯縣三九都圳仔地 | AE25: 賣 斷 契 單 | 福建國稅廳籌備處 | AF25: 福建國稅廳籌備處 | AG25: 方潮清 | AH25: 驗字第萬二千四百六十八號 | AI25: 0 | AJ25: 0 | AK25: 0 | AL25: 0 | AM25: 0 | AN25: 0 | AO25: 0 | AP25: 0 | AQ25: 0 | AR25: 0 | AS25: 1 | AT25: 0 | AU25: 0 | AV25: 0 | AW25: 0 | AX25: 1 | AY25: 1 | AZ25: 1 | BA25: 1 | BB25: 1 | BC25: 352 | BD25: 0 | BE25: 0 | BF25: 0 | BG25: https://digital.library.pitt.edu/islandora/object/pitt:31735064607587 | BH25: 賣斷契單福建國稅廳籌備處給發契單十案奉財政部電劃一契紙章程內開本章程施行以前成立之不動產舊契無論已稅契未稅契均一律限期呈驗逾限不呈驗者於訴訟時不能作為憑據一併函知司法機關認真理以為匿驗者或等因奉此當經擬定分別徵收方法已稅之舊契每張收紙價壹元未稅之舊契每產價百元收紙價壹元其光復後新契已稅者不收紙價酌定正限三個月餘限兩個月逾期呈驗者分別加徵嚴罰經已電奉財政部核辦並通飭遵照在案今據閩侯縣業戶方潮清於清同治拾年拾二月日買受先慈田地貳畝分界坐落閩侯縣三九都圳仔地地方東至西至北至坐落坐向橫丈尺直丈尺中證方濃官原價銀兩申銀壹百壹拾伍元原契未稅遵章依限呈驗應納紙價壹元貳角半已如數收訖合填契單粘連原契印給收執管業須至契單者東水湯井銀元北督催處馬官右給業戶方潮清准此中華民國貳年拾壹月叁拾日給驗字第萬二千四百六十八號
A26: 31735064607587_004 | B26: 31735064607587 | C26: 4 | D26: 1871 | E26: 1913 | F26: =IF(D26="","?",IF(D26<1796,"pre-1796",IF(D26<1912,"1796-1911",IF(D26<1949,"1912-1948","1949+")))) -> 1796-1911 | G26: =IF(D26="","?",IF(D26<1912,"Qing",IF(D26<1949,"Republic","PRC"))) -> Qing | H26: 1871/1913 | I26: 閩侯（閩縣・侯官・林森） | J26: 福建省閩侯縣 | K26: Government | M26: 方元慈 | N26: 方潮濤 | O26: Box 1, Folder 50 | P26: Official form | R26: 中華民國 41 年 | W26: ...係...東...者...博 | AI26: 0 | AJ26: 0 | AK26: 0 | AL26: 0 | AM26: 0 | AN26: 0 | AO26: 0 | AP26: 0 | AQ26: 0 | AR26: 0 | AS26: 0 | AT26: 0 | AU26: 0 | AV26: 0 | AW26: 0 | AX26: 0 | AY26: 0 | AZ26: 0 | BA26: 0 | BB26: 0 | BC26: 144 | BD26: 4 | BE26: 1 | BF26: 0 | BG26: https://digital.library.pitt.edu/islandora/object/pitt:31735064607587 | BH26: 此處粘連原契騎縫加蓋驗契鈐記此處蓋財政廳驗契證關防此處蓋縣府印第區區長簽名蓋章中華民國41年6月11日第49740號第保保長或鄉長簽名蓋章此種已稅契驗契證收驗費閩侯縣三此張填給業主粘連原契管業日買...慈田...畝分...坐落...係...東...者...博...北...身...至...
A27: 31735064607595_001 | B27: 31735064607595 | C27: 1 | D27: 1932 | E27: 1932 | F27: =IF(D27="","?",IF(D27<1796,"pre-1796",IF(D27<1912,"1796-1911",IF(D27<1949,"1912-1948","1949+")))) -> 1912-1948 | G27: =IF(D27="","?",IF(D27<1912,"Qing",IF(D27<1949,"Republic","PRC"))) -> Republic | H27: 1932 | I27: 閩清 | J27: 福建省閩清縣 | K27: Government | M27: 劉振萬 | N27: 劉紀臣 | O27: Box 3, Folder 145 | P27: Private deed + state certificate | Q27: 立賣新契 | R27: 中華民國二十一年 | S27: 劉振萬劉 | U27: 價大洋律拾肆員正 | V27: 大洋 | Y27: 民田 | Z27: 叔培貴鑒 | AB27: 姪維興叩 | AI27: 0 | AJ27: 0 | AK27: 0 | AL27: 1 | AM27: 1 | AN27: 1 | AO27: 0 | AP27: 0 | AQ27: 1 | AR27: 1 | AS27: 1 | AT27: 0 | AU27: 0 | AV27: 0 | AW27: 0 | AX27: 0 | AY27: 0 | AZ27: 0 | BA27: 0 | BB27: 0 | BC27: 244 | BD27: 1 | BE27: 0 | BF27: 0 | BG27: https://digital.library.pitt.edu/islandora/object/pitt:31735064607595 | BH27: 立賣新契劉振萬自已手置有民田報面全壺號坐地本鄉地方去名東埔頭並舊園厝迹田式均受種棟外其私照縣例斜派立立劉汝俊不台因要用稅中將此田賣斷契劉紀臣處永遠為業三面言改即日約記田斷價大洋律拾肆員正其銀隨契交足其田下聽臣維佃永遠耕作業理納租差但此田係萬自已物業與別契于並若重張與賣他人財物以及來歷不同皆情若有些情萬出拆不清臣之事自賣斷之後李筆千秋各彬欣喜不得異言亦不得別生枝節之理沿口若遇言教有過立賣斷契壹紙永作為照中華民國二十一年十一月日立賣新契劉振萬劉左見姪維興叩中人叔培貴鑒秉筆中弟振財劉劉振萬
A28: 31735064607595_002 | B28: 31735064607595 | C28: 2 | D28: 1932 | E28: 1932 | F28: =IF(D28="","?",IF(D28<1796,"pre-1796",IF(D28<1912,"1796-1911",IF(D28<1949,"1912-1948","1949+")))) -> 1912-1948 | G28: =IF(D28="","?",IF(D28<1912,"Qing",IF(D28<1949,"Republic","PRC"))) -> Republic | H28: 1932 | I28: 閩清 | J28: 福建省閩清縣 | K28: Government | M28: 劉振萬 | N28: 劉紀臣 | O28: Box 3, Folder 145 | P28: Official form | V28: 國幣 | AE28: 契稅暫行條例摘 | 要： | 財政部福建省 縣(市)田賦管理處賣契本契 | AI28: 0 | AJ28: 0 | AK28: 0 | AL28: 0 | AM28: 0 | AN28: 0 | AO28: 0 | AP28: 0 | AQ28: 0 | AR28: 0 | AS28: 0 | AT28: 1 | AU28: 0 | AV28: 0 | AW28: 0 | AX28: 0 | AY28: 0 | AZ28: 0 | BA28: 1 | BB28: 0 | BC28: 297 | BD28: 0 | BE28: 0 | BF28: 0 | BG28: https://digital.library.pitt.edu/islandora/object/pitt:31735064607595 | BH28: 契稅暫行條例摘要：一、契稅稅率規定如左：一、賣契稅為其契價百分之十二、典契稅為其契價百分之六三、交換契稅為其契價百分之四四、贈與契稅為其契價百分之十二、契紙工本費每張納國幣二元三、完納契稅應于契約成立後三個月內為之逾限不納者應責令補納并科以應納契稅百分之十之罰鍰其後每再逾期二個月遞加百分之十至達納稅額之同數為止四、繳納契稅時如遇匿報或低估契價應令另換契紙按實改正補繳短納稅額並科以左例之罰鍰甲、匿報或低估契價未滿百分之二十者其短納稅額之半數乙、匿報或低估契價百分之二十以上未滿百分之五十者其短納稅額之同數丙、匿報或低估契價百分之五十以上者其短納稅額之二倍財政部福建省縣(市)田賦管理處賣契本契
A29: 31735064607603_001 | B29: 31735064607603 | C29: 1 | F29: =IF(D29="","?",IF(D29<1796,"pre-1796",IF(D29<1912,"1796-1911",IF(D29<1949,"1912-1948","1949+")))) -> ? | G29: =IF(D29="","?",IF(D29<1912,"Qing",IF(D29<1949,"Republic","PRC"))) -> ? | J29: 福建省 | K29: Government | O29: Box 4, Folder 211 | P29: Official form | R29: 中華民國 年 | AF29: 福建省人民政府 | AH29: 權狀禮字第三三號 | AI29: 0 | AJ29: 0 | AK29: 0 | AL29: 0 | AM29: 0 | AN29: 0 | AO29: 0 | AP29: 0 | AQ29: 0 | AR29: 0 | AS29: 0 | AT29: 0 | AU29: 0 | AV29: 0 | AW29: 0 | AX29: 0 | AY29: 0 | AZ29: 0 | BA29: 0 | BB29: 0 | BC29: 96 | BD29: 0 | BE29: 0 | BF29: 0 | BG29: https://digital.library.pitt.edu/islandora/object/pitt:31735064607603 | BH29: 省-III-20-366實測戶地圖租經國家福建省人民政府委員會福建省會第二區第二十四段第三四號宅地面積。畝口分八厘一毫。然所有權狀禮字第三三號[]中華民國年月日福建省政府民政廳發一比五尺百分之
A30: 31735064607611_001 | B30: 31735064607611 | C30: 1 | D30: 1925 | E30: 1925 | F30: =IF(D30="","?",IF(D30<1796,"pre-1796",IF(D30<1912,"1796-1911",IF(D30<1949,"1912-1948","1949+")))) -> 1912-1948 | G30: =IF(D30="","?",IF(D30<1912,"Qing",IF(D30<1949,"Republic","PRC"))) -> Republic | H30: 1925 | I30: 閩侯（閩縣・侯官・林森） | J30: 福建省閩侯縣 | K30: Government | M30: 張銓銓 | N30: 鄒道明 | O30: Box 3, Folder 123 | P30: Private deed | Q30: 立賣與契 | S30: 張銓銓 | T30: 鄒道明 | U30: 價銀肆拾兩正 | Y30: 厝屋; 地基 | AI30: 1 | AJ30: 0 | AK30: 1 | AL30: 1 | AM30: 1 | AN30: 1 | AO30: 0 | AP30: 0 | AQ30: 1 | AR30: 1 | AS30: 1 | AT30: 0 | AU30: 0 | AV30: 0 | AW30: 0 | AX30: 0 | AY30: 0 | AZ30: 0 | BA30: 0 | BB30: 0 | BC30: 317 | BD30: 0 | BE30: 0 | BF30: 0 | BG30: https://digital.library.pitt.edu/islandora/object/pitt:31735064607611 | BH30: 立賣與契張銓銓承嗣父遺下閩分份下原有厝屋三柱式棚排重座共成式堵上有樑椽磚瓦天天下有地基石地地內有門懸戶棚地棚板粒一切具全橫濶至我丈式尺深至重丈四尺東才至前家屋右至游家路前至鄭家簷坪後至蘇家墻坪六至其俱明白厝角水井通用甲座產閩邑嘉崇里文山鋪秋龍社地方其屋歷掌無異今因別用將此厝屋托中向賣與鄒道明處永遠為業三面言議即日得訖賣與王之重價銀肆拾兩正紋廣其銀即日收足其屋即聽買主掌管前去從便做作聽從買主之事與銓本點無干但此屋係銓承嗣父遺下閩分份下已業與房內親疎伯叔兄弟侄輩本點無干亦未曾重張典掛他人財物以及未歷不明各等情如有此情係銓承嗣父當與買主無涉之事賣與之後價足心愿不得別生製節求斷其永不得異言兩相心愿各無反悔今欵有憑立主斷契委低付此永為憑
A31: 31735064607611_002 | B31: 31735064607611 | C31: 2 | D31: 1925 | E31: 1925 | F31: =IF(D31="","?",IF(D31<1796,"pre-1796",IF(D31<1912,"1796-1911",IF(D31<1949,"1912-1948","1949+")))) -> 1912-1948 | G31: =IF(D31="","?",IF(D31<1912,"Qing",IF(D31<1949,"Republic","PRC"))) -> Republic | H31: 1925 | I31: 閩侯（閩縣・侯官・林森） | J31: 福建省閩侯縣 | K31: Government | M31: 張銓銓 | N31: 鄒道明 | O31: Box 3, Folder 123 | P31: Official form | Q31: 立契 | R31: 民國二十三年 | AE31: 賣 | 新頒契紙 | 吳 | 列則摘要 | AI31: 0 | AJ31: 0 | AK31: 0 | AL31: 0 | AM31: 0 | AN31: 0 | AO31: 0 | AP31: 0 | AQ31: 0 | AR31: 0 | AS31: 0 | AT31: 0 | AU31: 0 | AV31: 0 | AW31: 0 | AX31: 0 | AY31: 0 | AZ31: 0 | BA31: 0 | BB31: 0 | BC31: 50 | BD31: 0 | BE31: 0 | BF31: 0 | BG31: https://digital.library.pitt.edu/islandora/object/pitt:31735064607611 | BH31: 號賣新頒契紙吳買王姓名儲商百壽協廣軒大種類牆屋價壹千應納稅額原契幾張立契年月日民國二十三年拾列則摘要
A32: 31735064607629_001 | B32: 31735064607629 | C32: 1 | D32: 1898 | E32: 1898 | F32: =IF(D32="","?",IF(D32<1796,"pre-1796",IF(D32<1912,"1796-1911",IF(D32<1949,"1912-1948","1949+")))) -> 1796-1911 | G32: =IF(D32="","?",IF(D32<1912,"Qing",IF(D32<1949,"Republic","PRC"))) -> Qing | H32: 1898 | K32: Personal | M32: 蘇章林 | N32: 劉仕懋 | O32: Box 2, Folder 80 | P32: Private deed | Q32: 立賣契 | R32: 光緒貳拾肆年 | S32: 蘇章林 | U32: 價紋銀叁拾貳兩正 | V32: 紋銀; 洋銀 | W32: 濠墩門前 | Y32: 皮骨 | Z32: 前來說諭即將其田 | AA32: 邱宗海 | AI32: 0 | AJ32: 1 | AK32: 0 | AL32: 1 | AM32: 0 | AN32: 0 | AO32: 0 | AP32: 1 | AQ32: 0 | AR32: 0 | AS32: 1 | AT32: 0 | AU32: 0 | AV32: 0 | AW32: 0 | AX32: 0 | AY32: 0 | AZ32: 0 | BA32: 0 | BB32: 0 | BC32: 383 | BD32: 0 | BE32: 0 | BF32: 0 | BG32: https://digital.library.pitt.edu/islandora/object/pitt:31735064607629 | BH32: 立賣契人蘇章林承祖遺下置有皮骨分定晚田坐落濠墩門前土名溪壁洲確下外郎目上至陳宅田下至楊宅田右至陳宅田右至本宅田為界原計大苗糙米壹籮七斛六管正該載民產壹畝零今來俱出四至產畝明白茲因缺少銀兩應用情愿托得中人前來說諭即將其田盡底立契出賣與長布村劉仕懋名下邊為業當日三面議土風時值契價紋銀叁拾貳兩正足成契之日一頓現交未欠分厘並非準折債貨之類及無重復興賣之理所賣其田的係自己分定物業與親房伯叔兄弟侄人等各無相涉自賣之後其田言議叁冬取贖办得原價即便退還如無原價任從買主營業收租賣者不敢阻攔此係前言後定兩家甘允各無後悔再無異說恐口無憑今欲有憑敬立賣契為照當日計批上手契卷與網房相共不便照後日尋出不堪行用一存太里之番五甲蘇廷林戶名當官完糧不得丟累存據當日實得契價紋銀叁拾貳兩正足訖另批中書洋銀壹兩伍錢貳分正光緒貳拾肆年十一月廿三賣契人蘇章林見銀人蘇章林說諭人劉仕德代筆人邱宗海蘇章林
A33: 31735064607637_001 | B33: 31735064607637 | C33: 1 | D33: 1945 | E33: 1945 | F33: =IF(D33="","?",IF(D33<1796,"pre-1796",IF(D33<1912,"1796-1911",IF(D33<1949,"1912-1948","1949+")))) -> 1912-1948 | G33: =IF(D33="","?",IF(D33<1912,"Qing",IF(D33<1949,"Republic","PRC"))) -> Republic | H33: 1945 | I33: 永泰（永福） | J33: 福建省永泰縣 | K33: Government | L33: 葉文怡 | O33: Box 3, Folder 167 | P33: Other / fragment | AE33: 支款凭证(代支出传票) | AI33: 0 | AJ33: 0 | AK33: 0 | AL33: 0 | AM33: 0 | AN33: 0 | AO33: 0 | AP33: 0 | AQ33: 0 | AR33: 0 | AS33: 0 | AT33: 0 | AU33: 0 | AV33: 0 | AW33: 0 | AX33: 0 | AY33: 0 | AZ33: 0 | BA33: 0 | BB33: 0 | BC33: 140 | BD33: 0 | BE33: 0 | BF33: 0 | BG33: https://digital.library.pitt.edu/islandora/object/pitt:31735064607637 | BH33: 支款凭证(代支出传票)总第号填发日期196年月日分第号借方科目农业收入转帐日期1963年2月18日对方科目支款单位名称项目内支款人姓名盖章帐号摘要付由62年收入转入分配金類万千百十元角分金額(大写)一万肆仟叁百壹拾元玖角貳分正631092第一联出納存根付款单位主管会计出納記帳制表
A34: 31735064607637_002 | B34: 31735064607637 | C34: 2 | D34: 1945 | E34: 1945 | F34: =IF(D34="","?",IF(D34<1796,"pre-1796",IF(D34<1912,"1796-1911",IF(D34<1949,"1912-1948","1949+")))) -> 1912-1948 | G34: =IF(D34="","?",IF(D34<1912,"Qing",IF(D34<1949,"Republic","PRC"))) -> Republic | H34: 1945 | I34: 永泰（永福） | J34: 福建省永泰縣 | K34: Government | L34: 葉文怡 | O34: Box 3, Folder 167 | P34: Official form | AI34: 0 | AJ34: 0 | AK34: 0 | AL34: 0 | AM34: 0 | AN34: 0 | AO34: 0 | AP34: 0 | AQ34: 0 | AR34: 0 | AS34: 0 | AT34: 0 | AU34: 0 | AV34: 0 | AW34: 0 | AX34: 0 | AY34: 0 | AZ34: 0 | BA34: 0 | BB34: 0 | BC34: 9 | BD34: 0 | BE34: 0 | BF34: 0 | BG34: https://digital.library.pitt.edu/islandora/object/pitt:31735064607637 | BH34: 月縣長兼處長副處長
A35: 31735064607637_003 | B35: 31735064607637 | C35: 3 | D35: 1945 | E35: 1945 | F35: =IF(D35="","?",IF(D35<1796,"pre-1796",IF(D35<1912,"1796-1911",IF(D35<1949,"1912-1948","1949+")))) -> 1912-1948 | G35: =IF(D35="","?",IF(D35<1912,"Qing",IF(D35<1949,"Republic","PRC"))) -> Republic | H35: 1945 | I35: 永泰（永福） | J35: 福建省永泰縣 | K35: Government | L35: 葉文怡 | O35: Box 3, Folder 167 | P35: Official form | R35: 中華民國三十四年 | Y35: 基地 | AE35: 梧 字 第 3994 號 | 福建省永泰縣 土地管業執照 | AF35: 照永泰縣政府 | AG35: 葉文怡 | AH35: 梧字第 105 號 | AI35: 0 | AJ35: 0 | AK35: 0 | AL35: 0 | AM35: 0 | AN35: 0 | AO35: 0 | AP35: 0 | AQ35: 0 | AR35: 0 | AS35: 0 | AT35: 0 | AU35: 0 | AV35: 0 | AW35: 1 | AX35: 1 | AY35: 1 | AZ35: 1 | BA35: 0 | BB35: 0 | BC35: 294 | BD35: 0 | BE35: 0 | BF35: 0 | BG35: https://digital.library.pitt.edu/islandora/object/pitt:31735064607637 | BH35: 梧字第3994號福建省永泰縣土地管業執照永泰縣政府為發給土地管業執照事查本縣奉令舉辦土地陳報右記業主地畝業經審核無訛合行填發管業執照以憑管業嗣後如有買賣典當繼承分割合併贈與交換或其他產權移轉時一除典權外一務須持照遵章向本縣田賦機關聲請推收過戶換領新照倘有偽造或私擅塗改按律治罪須至執照者地主姓名土地座落地目等則面積賦額全年收益地價葉文怡梧桐鄉鎮土名橫樓梧字第105號基地式下340畝九分捌厘0元壹角叁分元斤分附記[35(top),34(right),17(bottom),and10(北)南)東)西)totheleft.]比例尺1:2000中華民國三十四年右給葉文怡收執縣長兼處長副處長日
A36: 31735064607645_001 | B36: 31735064607645 | C36: 1 | D36: 1891 | E36: 1891 | F36: =IF(D36="","?",IF(D36<1796,"pre-1796",IF(D36<1912,"1796-1911",IF(D36<1949,"1912-1948","1949+")))) -> 1796-1911 | G36: =IF(D36="","?",IF(D36<1912,"Qing",IF(D36<1949,"Republic","PRC"))) -> Qing | H36: 1891 | K36: Personal | L36: 林萬開 | O36: Box 2, Folder 74 | P36: Other / fragment | Q36: 立閭書 | S36: 林萬開偕 | Y36: 屋宇; 山場 | AI36: 0 | AJ36: 0 | AK36: 0 | AL36: 0 | AM36: 0 | AN36: 0 | AO36: 0 | AP36: 0 | AQ36: 0 | AR36: 0 | AS36: 0 | AT36: 0 | AU36: 0 | AV36: 0 | AW36: 0 | AX36: 0 | AY36: 0 | AZ36: 0 | BA36: 0 | BB36: 0 | BC36: 283 | BD36: 0 | BE36: 0 | BF36: 0 | BG36: https://digital.library.pitt.edu/islandora/object/pitt:31735064607645 | BH36: 立閭書林萬開偕弟萬拱等蓋聞棣華競秀四玉相輝荆樹交柯三珠並耀誠盛事也我儀圖之顧藉式好而臚歡自叶雁行之美亦因分勞而折箸尤徵燕翼之周斯一家各凜肩承辛勤共喻即百產亦知掌管子姓長綿矣茲者兄弟商議敬擇良月邀請親友將承父遺物業及手置田園屋宇山場樹木等項除撥長子長孫份外其餘高低相搭肥瘦相兼在祖宗堂前按照福祿壽三房勻作三股均分拈閭為定各掌各業向後不得爭長競短庶幾無負前人貽謀之計抑且以杜後來攘奪之端其宗族之幸多矣伏願自閭分之後各自摒擋須半粟一絲常思儉約五風十雨勿廢勤勞同胞貴有同心還期臂助分產當知分任莫懈躬親兄宜弟弟亦宜兄聯枝衍慶子生孫孫復生子奕葉流馨長發其祥克昌厥後有厚望焉是為序
A37: 31735064607645_002 | B37: 31735064607645 | C37: 2 | D37: 1891 | E37: 1891 | F37: =IF(D37="","?",IF(D37<1796,"pre-1796",IF(D37<1912,"1796-1911",IF(D37<1949,"1912-1948","1949+")))) -> 1796-1911 | G37: =IF(D37="","?",IF(D37<1912,"Qing",IF(D37<1949,"Republic","PRC"))) -> Qing | H37: 1891 | K37: Personal | L37: 林萬開 | O37: Box 2, Folder 74 | P37: Other / fragment | U37: 錢伍拾文 | Y37: 厝屋 | AI37: 0 | AJ37: 0 | AK37: 0 | AL37: 0 | AM37: 0 | AN37: 0 | AO37: 0 | AP37: 0 | AQ37: 0 | AR37: 0 | AS37: 0 | AT37: 0 | AU37: 0 | AV37: 0 | AW37: 0 | AX37: 0 | AY37: 0 | AZ37: 0 | BA37: 0 | BB37: 0 | BC37: 167 | BD37: 2 | BE37: 0 | BF37: 0 | BG37: https://digital.library.pitt.edu/islandora/object/pitt:31735064607645 | BH37: 計開長子長孫份下一田土名井嘴根面全壺畝叁分水壑壺口一田土名馬路下根面全壺畝式分水壑壺口此二號糧色均立在草市都五甲林鎮戶下一田土名坑裡根面全壺畝水壑壺口此項田貼與福房年例三年施食一年上厝西澗出海各用耗其糧色附在草市都五甲林鎮戶下其田尾所栽松栢楸係為祖墓風水不得砍伐福房份下一厝屋前進二欄年貼納完糧錢伍拾文一厝邊牛欄一堵一典楊定亨厝屋壺欄
A38: 31735064607645_003 | B38: 31735064607645 | C38: 3 | D38: 1891 | E38: 1891 | F38: =IF(D38="","?",IF(D38<1796,"pre-1796",IF(D38<1912,"1796-1911",IF(D38<1949,"1912-1948","1949+")))) -> 1796-1911 | G38: =IF(D38="","?",IF(D38<1912,"Qing",IF(D38<1949,"Republic","PRC"))) -> Qing | H38: 1891 | K38: Personal | L38: 林萬開 | O38: Box 2, Folder 74 | P38: Other / fragment | X38: 壇路根; 長坵根 | AI38: 0 | AJ38: 0 | AK38: 0 | AL38: 0 | AM38: 0 | AN38: 0 | AO38: 0 | AP38: 0 | AQ38: 0 | AR38: 0 | AS38: 0 | AT38: 0 | AU38: 0 | AV38: 0 | AW38: 0 | AX38: 0 | AY38: 0 | AZ38: 0 | BA38: 0 | BB38: 0 | BC38: 179 | BD38: 0 | BE38: 0 | BF38: 0 | BG38: https://digital.library.pitt.edu/islandora/object/pitt:31735064607645 | BH38: 一草倉馬路松楸下壺欄一田白龍土名根面全式畝壺分零糧色立在三十六都六甲林溥戶下一田白龍土名圓坵根面全捌分零糧色立在三十六都十甲林維豪戶下一田湖尾土名長坵根面全式畝式分零糧色立在三十六都七甲林昌元戶下一田后圳土名四角橫坵根面全捌分零典久溜夾片壑應半壑水用糧色立在三十六都四甲林均戶下一田白龍土名壇路根田式畝伍分年納本鄉王處面租穀叁百伍拾斤一田白龍土名長坵根田壺畝
A39: 31735064607645_004 | B39: 31735064607645 | C39: 4 | D39: 1891 | E39: 1891 | F39: =IF(D39="","?",IF(D39<1796,"pre-1796",IF(D39<1912,"1796-1911",IF(D39<1949,"1912-1948","1949+")))) -> 1796-1911 | G39: =IF(D39="","?",IF(D39<1912,"Qing",IF(D39<1949,"Republic","PRC"))) -> Qing | H39: 1891 | K39: Personal | L39: 林萬開 | O39: Box 2, Folder 74 | P39: Other / fragment | U39: 價陸拾兩 | Y39: 田面 | AI39: 0 | AJ39: 0 | AK39: 0 | AL39: 0 | AM39: 0 | AN39: 0 | AO39: 0 | AP39: 0 | AQ39: 0 | AR39: 0 | AS39: 0 | AT39: 0 | AU39: 0 | AV39: 0 | AW39: 0 | AX39: 0 | AY39: 0 | AZ39: 0 | BA39: 0 | BB39: 0 | BC39: 146 | BD39: 0 | BE39: 0 | BF39: 0 | BG39: https://digital.library.pitt.edu/islandora/object/pitt:31735064607645 | BH39: 年儀納福城林家面租穀壹百叁拾陸斤一田面租年共叁百柒拾捌斤糧色附在草市都五甲林鎮戶下一田林克江年應各壹百伍拾肆斤現耕林可廷一佃王聯環王聯豪林昌興昌國年應柒拾斤現耕林克品王鳳灼林可廷一田北馬鞍用價陸拾兩年應乾淨穀陸百斤現耕蘇長育此項王梅出閣貼用一糞池馬路厝仔邊壹口一糞池臺前大路邊壹口又糞池地壹塊
A40: 31735064607645_005 | B40: 31735064607645 | C40: 5 | D40: 1891 | E40: 1891 | F40: =IF(D40="","?",IF(D40<1796,"pre-1796",IF(D40<1912,"1796-1911",IF(D40<1949,"1912-1948","1949+")))) -> 1796-1911 | G40: =IF(D40="","?",IF(D40<1912,"Qing",IF(D40<1949,"Republic","PRC"))) -> Qing | H40: 1891 | K40: Personal | L40: 林萬開 | O40: Box 2, Folder 74 | P40: Other / fragment | U40: 錢肆百文 | Y40: 厝屋 | AE40: 祿房份下 | AI40: 0 | AJ40: 0 | AK40: 0 | AL40: 0 | AM40: 0 | AN40: 0 | AO40: 0 | AP40: 0 | AQ40: 0 | AR40: 0 | AS40: 0 | AT40: 0 | AU40: 0 | AV40: 0 | AW40: 0 | AX40: 0 | AY40: 0 | AZ40: 0 | BA40: 0 | BB40: 0 | BC40: 196 | BD40: 1 | BE40: 0 | BF40: 0 | BG40: https://digital.library.pitt.edu/islandora/object/pitt:31735064607645 | BH40: 祿房份下一厝屋第三進二櫚披水壺櫚其門路由二進出入喜喪事二進大廳通用年納楊家地租伍拾文一厝屋楊家隔壁壺櫚一草倉祠堂下壺櫚一田湖尾土名水流路根面全叁畝叁分糧色立在三十六都二圖二甲林開戶下又納倪家禾租肆拾斤折錢肆百文一田湖尾土名流道應半根面全壺畝壹分糧色立在三十六都二圖二甲林春戶下又買斷可真典與白龍張家應半田底一田湖尾土名豬蹄坵根面全壺畝叁分典契價壺百兩又借式拾兩糧色立在三十六都二圖四甲林均戶下
...

Sheet Narrative_moves
A1: The 12 narrative moves of a private deed
A2: Counts = private-deed pages (incl. deed + certificate) where the move's search pattern appears in the OCR text. Lower bounds: OCR misreads hide some instances.
A4: # | B4: Move | C4: Typical formula | D4: Function | E4: Flag column in Documents | F4: Pages with move | G4: Private pages | H4: Share
A5: 1 | B5: Title & author | C5: 立〔賣斷〕契 + name | D5: Names the contract by legal type and its author | E5: (not auto-detected) | G5: =COUNTIF(Documents!$P$2:$P$408,"Private deed*") -> 118
A6: 2 | B6: Provenance | C6: 承祖 / 承父手置 / 鬮書份下 | D6: Ownership told as inheritance | E6: (not auto-detected) | G6: =COUNTIF(Documents!$P$2:$P$408,"Private deed*") -> 118
A7: 3 | B7: Description | C7: 坐落…土名… / 四至 / 受種 / 年載租 | D7: Land located by native place-name, measured by seed and rent | E7: (not auto-detected) | G7: =COUNTIF(Documents!$P$2:$P$408,"Private deed*") -> 118
A8: 4 | B8: Motive | C8: 今因要用 / 別置 / 無錢應用 | D8: Turning point; reason kept formulaic | E8: 今因 motive | F8: =COUNTIFS(Documents!$P$2:$P$408,"Private deed*",Documents!$AI$2:$AI$408,1) -> 83 | G8: =COUNTIF(Documents!$P$2:$P$408,"Private deed*") -> 118 | H8: =IFERROR(F8/G8,0) -> 0.70338983
A9: 5 | B9: Voluntariness | C9: 自願 | D9: Seller acts of own will | E9: 自願 voluntary | F9: =COUNTIFS(Documents!$P$2:$P$408,"Private deed*",Documents!$AJ$2:$AJ$408,1) -> 47 | G9: =COUNTIF(Documents!$P$2:$P$408,"Private deed*") -> 118 | H9: =IFERROR(F9/G9,0) -> 0.39830508
A10: 6 | B10: Mediation | C10: 託中 … 賣與 ⏎ X處為業 | D10: Middleman; buyer name often raised to a new line (抬頭) | E10: 託中 mediated | F10: =COUNTIFS(Documents!$P$2:$P$408,"Private deed*",Documents!$AK$2:$AK$408,1) -> 79 | G10: =COUNTIF(Documents!$P$2:$P$408,"Private deed*") -> 118 | H10: =IFERROR(F10/G10,0) -> 0.66949153
A11: 7 | B11: Agreement & price | C11: 三面言議 … 價銀…正 | D11: Three-party agreement; formal numerals closed by 正 | E11: 三面言議 | F11: =COUNTIFS(Documents!$P$2:$P$408,"Private deed*",Documents!$AL$2:$AL$408,1) -> 71 | G11: =COUNTIF(Documents!$P$2:$P$408,"Private deed*") -> 118 | H11: =IFERROR(F11/G11,0) -> 0.60169492
A12: 8 | B12: Payment | C12: 其銀即日隨契交足 | D12: Payment complete at writing | E12: 即日交足 paid | F12: =COUNTIFS(Documents!$P$2:$P$408,"Private deed*",Documents!$AM$2:$AM$408,1) -> 93 | G12: =COUNTIF(Documents!$P$2:$P$408,"Private deed*") -> 118 | H12: =IFERROR(F12/G12,0) -> 0.78813559
A13: 9 | B13: Warranty | C13: 未曾重張典當…來歷不明 | D13: Negates every possible prior claim | E13: 無重典/來歷 warranty | F13: =COUNTIFS(Documents!$P$2:$P$408,"Private deed*",Documents!$AN$2:$AN$408,1) -> 77 | G13: =COUNTIF(Documents!$P$2:$P$408,"Private deed*") -> 118 | H13: =IFERROR(F13/G13,0) -> 0.65254237
A14: 10 | B14: Liability | C14: 出頭承當，不涉X之事 | D14: Seller answers any claim | E14: 出頭承當 seller answers | F14: =COUNTIFS(Documents!$P$2:$P$408,"Private deed*",Documents!$AO$2:$AO$408,1) -> 71 | G14: =COUNTIF(Documents!$P$2:$P$408,"Private deed*") -> 118 | H14: =IFERROR(F14/G14,0) -> 0.60169492
A15: 11 | B15: Time clause | C15: 面約…年為限…取贖 / 永斷萬無 | D15: Redemption window or permanent closure | E15: 取贖 redemption | F15: =COUNTIFS(Documents!$P$2:$P$408,"Private deed*",Documents!$AP$2:$AP$408,1) -> 40 | G15: =COUNTIF(Documents!$P$2:$P$408,"Private deed*") -> 118 | H15: =IFERROR(F15/G15,0) -> 0.33898305
A16: 12 | B16: Closing | C16: 兩相允願，各無反悔。今欲有憑，立…壹紙為照 | D16: The paper itself as proof | E16: 今欲有憑 closing | F16: =COUNTIFS(Documents!$P$2:$P$408,"Private deed*",Documents!$AS$2:$AS$408,1) -> 112 | G16: =COUNTIF(Documents!$P$2:$P$408,"Private deed*") -> 118 | H16: =IFERROR(F16/G16,0) -> 0.94915254

Sheet Formulae_by_period
A1: Private-deed formulae by period
A2: Each cell: number of private-deed pages in that period whose OCR text contains the formula. Period = catalogue start year.
A4: Formula | B4: pre-1796 | C4: 1796-1911 | D4: 1912-1948 | E4: 1949+ | F4: ? | G4: Total | H4: pre-1796 % | I4: 1796-1911 % | J4: 1912-1948 %
A5: Private pages (base) | B5: =COUNTIFS(Documents!$P$2:$P$408,"Private deed*",Documents!$F$2:$F$408,"pre-1796") -> 9 | C5: =COUNTIFS(Documents!$P$2:$P$408,"Private deed*",Documents!$F$2:$F$408,"1796-1911") -> 58 | D5: =COUNTIFS(Documents!$P$2:$P$408,"Private deed*",Documents!$F$2:$F$408,"1912-1948") -> 43 | E5: =COUNTIFS(Documents!$P$2:$P$408,"Private deed*",Documents!$F$2:$F$408,"1949+") -> 5 | F5: =COUNTIFS(Documents!$P$2:$P$408,"Private deed*",Documents!$F$2:$F$408,"?") -> 3 | G5: =SUM(B5:F5) -> 118
A6: 今因 motive | B6: =COUNTIFS(Documents!$P$2:$P$408,"Private deed*",Documents!$F$2:$F$408,"pre-1796",Documents!$AI$2:$AI$408,1) -> 4 | C6: =COUNTIFS(Documents!$P$2:$P$408,"Private deed*",Documents!$F$2:$F$408,"1796-1911",Documents!$AI$2:$AI$408,1) -> 46 | D6: =COUNTIFS(Documents!$P$2:$P$408,"Private deed*",Documents!$F$2:$F$408,"1912-1948",Documents!$AI$2:$AI$408,1) -> 29 | E6: =COUNTIFS(Documents!$P$2:$P$408,"Private deed*",Documents!$F$2:$F$408,"1949+",Documents!$AI$2:$AI$408,1) -> 1 | F6: =COUNTIFS(Documents!$P$2:$P$408,"Private deed*",Documents!$F$2:$F$408,"?",Documents!$AI$2:$AI$408,1) -> 3 | G6: =SUM(B6:F6) -> 83 | H6: =IFERROR(B6/B$5,0) -> 0.44444444 | I6: =IFERROR(C6/C$5,0) -> 0.79310345 | J6: =IFERROR(D6/D$5,0) -> 0.6744186
A7: 自願 voluntary | B7: =COUNTIFS(Documents!$P$2:$P$408,"Private deed*",Documents!$F$2:$F$408,"pre-1796",Documents!$AJ$2:$AJ$408,1) -> 3 | C7: =COUNTIFS(Documents!$P$2:$P$408,"Private deed*",Documents!$F$2:$F$408,"1796-1911",Documents!$AJ$2:$AJ$408,1) -> 27 | D7: =COUNTIFS(Documents!$P$2:$P$408,"Private deed*",Documents!$F$2:$F$408,"1912-1948",Documents!$AJ$2:$AJ$408,1) -> 15 | E7: =COUNTIFS(Documents!$P$2:$P$408,"Private deed*",Documents!$F$2:$F$408,"1949+",Documents!$AJ$2:$AJ$408,1) -> 1 | F7: =COUNTIFS(Documents!$P$2:$P$408,"Private deed*",Documents!$F$2:$F$408,"?",Documents!$AJ$2:$AJ$408,1) -> 1 | G7: =SUM(B7:F7) -> 47 | H7: =IFERROR(B7/B$5,0) -> 0.33333333 | I7: =IFERROR(C7/C$5,0) -> 0.46551724 | J7: =IFERROR(D7/D$5,0) -> 0.34883721
A8: 託中 mediated | B8: =COUNTIFS(Documents!$P$2:$P$408,"Private deed*",Documents!$F$2:$F$408,"pre-1796",Documents!$AK$2:$AK$408,1) -> 4 | C8: =COUNTIFS(Documents!$P$2:$P$408,"Private deed*",Documents!$F$2:$F$408,"1796-1911",Documents!$AK$2:$AK$408,1) -> 45 | D8: =COUNTIFS(Documents!$P$2:$P$408,"Private deed*",Documents!$F$2:$F$408,"1912-1948",Documents!$AK$2:$AK$408,1) -> 26 | E8: =COUNTIFS(Documents!$P$2:$P$408,"Private deed*",Documents!$F$2:$F$408,"1949+",Documents!$AK$2:$AK$408,1) -> 2 | F8: =COUNTIFS(Documents!$P$2:$P$408,"Private deed*",Documents!$F$2:$F$408,"?",Documents!$AK$2:$AK$408,1) -> 2 | G8: =SUM(B8:F8) -> 79 | H8: =IFERROR(B8/B$5,0) -> 0.44444444 | I8: =IFERROR(C8/C$5,0) -> 0.77586207 | J8: =IFERROR(D8/D$5,0) -> 0.60465116
A9: 三面言議 | B9: =COUNTIFS(Documents!$P$2:$P$408,"Private deed*",Documents!$F$2:$F$408,"pre-1796",Documents!$AL$2:$AL$408,1) -> 3 | C9: =COUNTIFS(Documents!$P$2:$P$408,"Private deed*",Documents!$F$2:$F$408,"1796-1911",Documents!$AL$2:$AL$408,1) -> 40 | D9: =COUNTIFS(Documents!$P$2:$P$408,"Private deed*",Documents!$F$2:$F$408,"1912-1948",Documents!$AL$2:$AL$408,1) -> 25 | E9: =COUNTIFS(Documents!$P$2:$P$408,"Private deed*",Documents!$F$2:$F$408,"1949+",Documents!$AL$2:$AL$408,1) -> 3 | F9: =COUNTIFS(Documents!$P$2:$P$408,"Private deed*",Documents!$F$2:$F$408,"?",Documents!$AL$2:$AL$408,1) -> 0 | G9: =SUM(B9:F9) -> 71 | H9: =IFERROR(B9/B$5,0) -> 0.33333333 | I9: =IFERROR(C9/C$5,0) -> 0.68965517 | J9: =IFERROR(D9/D$5,0) -> 0.58139535
A10: 即日交足 paid | B10: =COUNTIFS(Documents!$P$2:$P$408,"Private deed*",Documents!$F$2:$F$408,"pre-1796",Documents!$AM$2:$AM$408,1) -> 6 | C10: =COUNTIFS(Documents!$P$2:$P$408,"Private deed*",Documents!$F$2:$F$408,"1796-1911",Documents!$AM$2:$AM$408,1) -> 47 | D10: =COUNTIFS(Documents!$P$2:$P$408,"Private deed*",Documents!$F$2:$F$408,"1912-1948",Documents!$AM$2:$AM$408,1) -> 33 | E10: =COUNTIFS(Documents!$P$2:$P$408,"Private deed*",Documents!$F$2:$F$408,"1949+",Documents!$AM$2:$AM$408,1) -> 4 | F10: =COUNTIFS(Documents!$P$2:$P$408,"Private deed*",Documents!$F$2:$F$408,"?",Documents!$AM$2:$AM$408,1) -> 3 | G10: =SUM(B10:F10) -> 93 | H10: =IFERROR(B10/B$5,0) -> 0.66666667 | I10: =IFERROR(C10/C$5,0) -> 0.81034483 | J10: =IFERROR(D10/D$5,0) -> 0.76744186
A11: 無重典/來歷 warranty | B11: =COUNTIFS(Documents!$P$2:$P$408,"Private deed*",Documents!$F$2:$F$408,"pre-1796",Documents!$AN$2:$AN$408,1) -> 5 | C11: =COUNTIFS(Documents!$P$2:$P$408,"Private deed*",Documents!$F$2:$F$408,"1796-1911",Documents!$AN$2:$AN$408,1) -> 39 | D11: =COUNTIFS(Documents!$P$2:$P$408,"Private deed*",Documents!$F$2:$F$408,"1912-1948",Documents!$AN$2:$AN$408,1) -> 29 | E11: =COUNTIFS(Documents!$P$2:$P$408,"Private deed*",Documents!$F$2:$F$408,"1949+",Documents!$AN$2:$AN$408,1) -> 1 | F11: =COUNTIFS(Documents!$P$2:$P$408,"Private deed*",Documents!$F$2:$F$408,"?",Documents!$AN$2:$AN$408,1) -> 3 | G11: =SUM(B11:F11) -> 77 | H11: =IFERROR(B11/B$5,0) -> 0.55555556 | I11: =IFERROR(C11/C$5,0) -> 0.67241379 | J11: =IFERROR(D11/D$5,0) -> 0.6744186
A12: 出頭承當 seller answers | B12: =COUNTIFS(Documents!$P$2:$P$408,"Private deed*",Documents!$F$2:$F$408,"pre-1796",Documents!$AO$2:$AO$408,1) -> 4 | C12: =COUNTIFS(Documents!$P$2:$P$408,"Private deed*",Documents!$F$2:$F$408,"1796-1911",Documents!$AO$2:$AO$408,1) -> 34 | D12: =COUNTIFS(Documents!$P$2:$P$408,"Private deed*",Documents!$F$2:$F$408,"1912-1948",Documents!$AO$2:$AO$408,1) -> 29 | E12: =COUNTIFS(Documents!$P$2:$P$408,"Private deed*",Documents!$F$2:$F$408,"1949+",Documents!$AO$2:$AO$408,1) -> 1 | F12: =COUNTIFS(Documents!$P$2:$P$408,"Private deed*",Documents!$F$2:$F$408,"?",Documents!$AO$2:$AO$408,1) -> 3 | G12: =SUM(B12:F12) -> 71 | H12: =IFERROR(B12/B$5,0) -> 0.44444444 | I12: =IFERROR(C12/C$5,0) -> 0.5862069 | J12: =IFERROR(D12/D$5,0) -> 0.6744186
A13: 取贖 redemption | B13: =COUNTIFS(Documents!$P$2:$P$408,"Private deed*",Documents!$F$2:$F$408,"pre-1796",Documents!$AP$2:$AP$408,1) -> 3 | C13: =COUNTIFS(Documents!$P$2:$P$408,"Private deed*",Documents!$F$2:$F$408,"1796-1911",Documents!$AP$2:$AP$408,1) -> 20 | D13: =COUNTIFS(Documents!$P$2:$P$408,"Private deed*",Documents!$F$2:$F$408,"1912-1948",Documents!$AP$2:$AP$408,1) -> 14 | E13: =COUNTIFS(Documents!$P$2:$P$408,"Private deed*",Documents!$F$2:$F$408,"1949+",Documents!$AP$2:$AP$408,1) -> 0 | F13: =COUNTIFS(Documents!$P$2:$P$408,"Private deed*",Documents!$F$2:$F$408,"?",Documents!$AP$2:$AP$408,1) -> 3 | G13: =SUM(B13:F13) -> 40 | H13: =IFERROR(B13/B$5,0) -> 0.33333333 | I13: =IFERROR(C13/C$5,0) -> 0.34482759 | J13: =IFERROR(D13/D$5,0) -> 0.3255814
A14: 永遠 perpetual | B14: =COUNTIFS(Documents!$P$2:$P$408,"Private deed*",Documents!$F$2:$F$408,"pre-1796",Documents!$AQ$2:$AQ$408,1) -> 2 | C14: =COUNTIFS(Documents!$P$2:$P$408,"Private deed*",Documents!$F$2:$F$408,"1796-1911",Documents!$AQ$2:$AQ$408,1) -> 28 | D14: =COUNTIFS(Documents!$P$2:$P$408,"Private deed*",Documents!$F$2:$F$408,"1912-1948",Documents!$AQ$2:$AQ$408,1) -> 23 | E14: =COUNTIFS(Documents!$P$2:$P$408,"Private deed*",Documents!$F$2:$F$408,"1949+",Documents!$AQ$2:$AQ$408,1) -> 0 | F14: =COUNTIFS(Documents!$P$2:$P$408,"Private deed*",Documents!$F$2:$F$408,"?",Documents!$AQ$2:$AQ$408,1) -> 0 | G14: =SUM(B14:F14) -> 53 | H14: =IFERROR(B14/B$5,0) -> 0.22222222 | I14: =IFERROR(C14/C$5,0) -> 0.48275862 | J14: =IFERROR(D14/D$5,0) -> 0.53488372
A15: 無反悔/異言 | B15: =COUNTIFS(Documents!$P$2:$P$408,"Private deed*",Documents!$F$2:$F$408,"pre-1796",Documents!$AR$2:$AR$408,1) -> 3 | C15: =COUNTIFS(Documents!$P$2:$P$408,"Private deed*",Documents!$F$2:$F$408,"1796-1911",Documents!$AR$2:$AR$408,1) -> 32 | D15: =COUNTIFS(Documents!$P$2:$P$408,"Private deed*",Documents!$F$2:$F$408,"1912-1948",Documents!$AR$2:$AR$408,1) -> 24 | E15: =COUNTIFS(Documents!$P$2:$P$408,"Private deed*",Documents!$F$2:$F$408,"1949+",Documents!$AR$2:$AR$408,1) -> 1 | F15: =COUNTIFS(Documents!$P$2:$P$408,"Private deed*",Documents!$F$2:$F$408,"?",Documents!$AR$2:$AR$408,1) -> 2 | G15: =SUM(B15:F15) -> 62 | H15: =IFERROR(B15/B$5,0) -> 0.33333333 | I15: =IFERROR(C15/C$5,0) -> 0.55172414 | J15: =IFERROR(D15/D$5,0) -> 0.55813953
A16: 今欲有憑 closing | B16: =COUNTIFS(Documents!$P$2:$P$408,"Private deed*",Documents!$F$2:$F$408,"pre-1796",Documents!$AS$2:$AS$408,1) -> 8 | C16: =COUNTIFS(Documents!$P$2:$P$408,"Private deed*",Documents!$F$2:$F$408,"1796-1911",Documents!$AS$2:$AS$408,1) -> 55 | D16: =COUNTIFS(Documents!$P$2:$P$408,"Private deed*",Documents!$F$2:$F$408,"1912-1948",Documents!$AS$2:$AS$408,1) -> 42 | E16: =COUNTIFS(Documents!$P$2:$P$408,"Private deed*",Documents!$F$2:$F$408,"1949+",Documents!$AS$2:$AS$408,1) -> 4 | F16: =COUNTIFS(Documents!$P$2:$P$408,"Private deed*",Documents!$F$2:$F$408,"?",Documents!$AS$2:$AS$408,1) -> 3 | G16: =SUM(B16:F16) -> 112 | H16: =IFERROR(B16/B$5,0) -> 0.88888889 | I16: =IFERROR(C16/C$5,0) -> 0.94827586 | J16: =IFERROR(D16/D$5,0) -> 0.97674419
A17: 併繳 prior deeds | B17: =COUNTIFS(Documents!$P$2:$P$408,"Private deed*",Documents!$F$2:$F$408,"pre-1796",Documents!$AT$2:$AT$408,1) -> 1 | C17: =COUNTIFS(Documents!$P$2:$P$408,"Private deed*",Documents!$F$2:$F$408,"1796-1911",Documents!$AT$2:$AT$408,1) -> 17 | D17: =COUNTIFS(Documents!$P$2:$P$408,"Private deed*",Documents!$F$2:$F$408,"1912-1948",Documents!$AT$2:$AT$408,1) -> 15 | E17: =COUNTIFS(Documents!$P$2:$P$408,"Private deed*",Documents!$F$2:$F$408,"1949+",Documents!$AT$2:$AT$408,1) -> 0 | F17: =COUNTIFS(Documents!$P$2:$P$408,"Private deed*",Documents!$F$2:$F$408,"?",Documents!$AT$2:$AT$408,1) -> 1 | G17: =SUM(B17:F17) -> 34 | H17: =IFERROR(B17/B$5,0) -> 0.11111111 | I17: =IFERROR(C17/C$5,0) -> 0.29310345 | J17: =IFERROR(D17/D$5,0) -> 0.34883721
A18: 內改 correction | B18: =COUNTIFS(Documents!$P$2:$P$408,"Private deed*",Documents!$F$2:$F$408,"pre-1796",Documents!$AU$2:$AU$408,1) -> 0 | C18: =COUNTIFS(Documents!$P$2:$P$408,"Private deed*",Documents!$F$2:$F$408,"1796-1911",Documents!$AU$2:$AU$408,1) -> 9 | D18: =COUNTIFS(Documents!$P$2:$P$408,"Private deed*",Documents!$F$2:$F$408,"1912-1948",Documents!$AU$2:$AU$408,1) -> 6 | E18: =COUNTIFS(Documents!$P$2:$P$408,"Private deed*",Documents!$F$2:$F$408,"1949+",Documents!$AU$2:$AU$408,1) -> 0 | F18: =COUNTIFS(Documents!$P$2:$P$408,"Private deed*",Documents!$F$2:$F$408,"?",Documents!$AU$2:$AU$408,1) -> 1 | G18: =SUM(B18:F18) -> 16 | H18: =IFERROR(B18/B$5,0) -> 0 | I18: =IFERROR(C18/C$5,0) -> 0.15517241 | J18: =IFERROR(D18/D$5,0) -> 0.13953488
A19: 吉日 | B19: =COUNTIFS(Documents!$P$2:$P$408,"Private deed*",Documents!$F$2:$F$408,"pre-1796",Documents!$AV$2:$AV$408,1) -> 0 | C19: =COUNTIFS(Documents!$P$2:$P$408,"Private deed*",Documents!$F$2:$F$408,"1796-1911",Documents!$AV$2:$AV$408,1) -> 24 | D19: =COUNTIFS(Documents!$P$2:$P$408,"Private deed*",Documents!$F$2:$F$408,"1912-1948",Documents!$AV$2:$AV$408,1) -> 4 | E19: =COUNTIFS(Documents!$P$2:$P$408,"Private deed*",Documents!$F$2:$F$408,"1949+",Documents!$AV$2:$AV$408,1) -> 0 | F19: =COUNTIFS(Documents!$P$2:$P$408,"Private deed*",Documents!$F$2:$F$408,"?",Documents!$AV$2:$AV$408,1) -> 0 | G19: =SUM(B19:F19) -> 28 | H19: =IFERROR(B19/B$5,0) -> 0 | I19: =IFERROR(C19/C$5,0) -> 0.4137931 | J19: =IFERROR(D19/D$5,0) -> 0.093023256

Sheet Official_formulae
A1: Bureaucratic formulae by regime
A2: Pages typed "Official form" or "Private deed + state certificate". Regime = catalogue start year (<1912 Qing, <1949 Republic, else PRC).
A4: Step | B4: Formula | C4: Function | D4: Qing | E4: Republic | F4: PRC | G4: Total
